Workbook

Sheet 1

Sheet 1- bogota
A1: TASAS Y DESEMBOLSOS MENSUALES DE CARTERA DE VIVIENDA
A2: BANCO DE BOGOTA
AG3: Cifras en millones de pesos y tasas efectivas anuales promedio ponderadas
A4: MES | B4: Construcción de Vivienda diferente de VIS en pesos | E4: Construcción de Vivienda diferente de VIS en UVR | H4: Construcción de Vivienda VIS en pesos | K4: Construcción de Vivienda VIS en UVR | N4: Adquisición de Vivienda diferente de VIS en Pesos | Q4: Adquisición de Vivienda diferente de VIS en UVR | T4: Adquisición de Vivienda VIS en Pesos | W4: Adquisición de Vivienda VIS en UVR | Z4: CREDITOS DE VIVIENDA en U.V.R. (Puntos) | AF4: CREDITOS DE VIVIENDA en Pesos (T.E.A.) | AL4: CONSOLIDADO
Z5: VIS | AC5: NO VIS | AF5: VIS | AI5: NO VIS | AL5: VIS | AN5: NO VIS
B6: TASA | C6: MONTO | D6: NÚMERO DE CRÉDITOS DESEMBOLSADOS | E6: TASA | F6: MONTO | G6: NÚMERO DE CRÉDITOS DESEMBOLSADOS | H6: TASA | I6: MONTO | J6: NÚMERO DE CRÉDITOS DESEMBOLSADOS | K6: TASA | L6: MONTO | M6: NÚMERO DE CRÉDITOS DESEMBOLSADOS | N6: TASA | O6: MONTO | P6: NÚMERO DE CRÉDITOS DESEMBOLSADOS | Q6: TASA | R6: MONTO | S6: NÚMERO DE CRÉDITOS DESEMBOLSADOS | T6: TASA | U6: MONTO | V6: NÚMERO DE CRÉDITOS DESEMBOLSADOS | W6: TASA | X6: MONTO | Y6: NÚMERO DE CRÉDITOS DESEMBOLSADOS | Z6: TASA | AA6: MONTO | AB6: NÚMERO DE CRÉDITOS DESEMBOLSADOS | AC6: TASA | AD6: MONTO | AE6: NÚMERO DE CRÉDITOS DESEMBOLSADOS | AF6: TASA | AG6: MONTO | AH6: NÚMERO DE CRÉDITOS DESEMBOLSADOS | AI6: TASA | AJ6: MONTO | AK6: NÚMERO DE CRÉDITOS DESEMBOLSADOS | AL6: MONTO | AM6: NÚMERO DE CRÉDITOS DESEMBOLSADOS | AN6: MONTO | AO6: NÚMERO DE CRÉDITOS DESEMBOLSADOS
A7: SEPTIEMBRE DE 2004 | W7: 11 | X7: 536.812 | Z7: =IF(AA7=0,"N.A.",((K7*L7)+(W7*X7))/AA7) -> 11 | AA7: =+L7+X7 -> 536.812 | AC7: =IF(AD7=0,"N.A.",((E7*F7)+(Q7*R7))/AD7) -> N.A. | AD7: =+F7+R7 -> 0 | AF7: =IF(AG7=0,"N.A.",((H7*I7)+(T7*U7))/AG7) -> N.A. | AG7: =+I7+U7 -> 0 | AI7: =IF(AJ7=0,"N.A.",((B7*C7)+(N7*O7))/AJ7) -> N.A. | AJ7: =+C7+O7 -> 0 | AL7: =+AA7+AG7 -> 536.812 | AM7: =+AB7+AH7 -> 0 | AN7: =+AD7+AJ7 -> 0 | AO7: =+AE7+AK7 -> 0
A8: OCTUBRE DE 2004 | W8: 11 | X8: 68.554 | Z8: =IF(AA8=0,"N.A.",((K8*L8)+(W8*X8))/AA8) -> 11 | AA8: =+L8+X8 -> 68.554 | AC8: =IF(AD8=0,"N.A.",((E8*F8)+(Q8*R8))/AD8) -> N.A. | AD8: =+F8+R8 -> 0 | AF8: =IF(AG8=0,"N.A.",((H8*I8)+(T8*U8))/AG8) -> N.A. | AG8: =+I8+U8 -> 0 | AI8: =IF(AJ8=0,"N.A.",((B8*C8)+(N8*O8))/AJ8) -> N.A. | AJ8: =+C8+O8 -> 0 | AL8: =+AA8+AG8 -> 68.554 | AM8: =+AB8+AH8 -> 0 | AN8: =+AD8+AJ8 -> 0 | AO8: =+AE8+AK8 -> 0
A9: NOVIEMBRE DE 2004 | W9: 11 | X9: 103.363 | Z9: =IF(AA9=0,"N.A.",((K9*L9)+(W9*X9))/AA9) -> 11 | AA9: =+L9+X9 -> 103.363 | AC9: =IF(AD9=0,"N.A.",((E9*F9)+(Q9*R9))/AD9) -> N.A. | AD9: =+F9+R9 -> 0 | AF9: =IF(AG9=0,"N.A.",((H9*I9)+(T9*U9))/AG9) -> N.A. | AG9: =+I9+U9 -> 0 | AI9: =IF(AJ9=0,"N.A.",((B9*C9)+(N9*O9))/AJ9) -> N.A. | AJ9: =+C9+O9 -> 0 | AL9: =+AA9+AG9 -> 103.363 | AM9: =+AB9+AH9 -> 0 | AN9: =+AD9+AJ9 -> 0 | AO9: =+AE9+AK9 -> 0
A10: DICIEMBRE DE 2004 | W10: 11 | X10: 132.877 | Z10: =IF(AA10=0,"N.A.",((K10*L10)+(W10*X10))/AA10) -> 11 | AA10: =+L10+X10 -> 132.877 | AC10: =IF(AD10=0,"N.A.",((E10*F10)+(Q10*R10))/AD10) -> N.A. | AD10: =+F10+R10 -> 0 | AF10: =IF(AG10=0,"N.A.",((H10*I10)+(T10*U10))/AG10) -> N.A. | AG10: =+I10+U10 -> 0 | AI10: =IF(AJ10=0,"N.A.",((B10*C10)+(N10*O10))/AJ10) -> N.A. | AJ10: =+C10+O10 -> 0 | AL10: =+AA10+AG10 -> 132.877 | AM10: =+AB10+AH10 -> 0 | AN10: =+AD10+AJ10 -> 0 | AO10: =+AE10+AK10 -> 0
A11: ENERO DE 2005 | W11: 11 | X11: 34.428 | Z11: =IF(AA11=0,"N.A.",((K11*L11)+(W11*X11))/AA11) -> 11 | AA11: =+L11+X11 -> 34.428 | AC11: =IF(AD11=0,"N.A.",((E11*F11)+(Q11*R11))/AD11) -> N.A. | AD11: =+F11+R11 -> 0 | AF11: =IF(AG11=0,"N.A.",((H11*I11)+(T11*U11))/AG11) -> N.A. | AG11: =+I11+U11 -> 0 | AI11: =IF(AJ11=0,"N.A.",((B11*C11)+(N11*O11))/AJ11) -> N.A. | AJ11: =+C11+O11 -> 0 | AL11: =+AA11+AG11 -> 34.428 | AM11: =+AB11+AH11 -> 0 | AN11: =+AD11+AJ11 -> 0 | AO11: =+AE11+AK11 -> 0
A12: FEBRERO DE 2005 | W12: 11 | X12: 337.484 | Z12: =IF(AA12=0,"N.A.",((K12*L12)+(W12*X12))/AA12) -> 11 | AA12: =+L12+X12 -> 337.484 | AC12: =IF(AD12=0,"N.A.",((E12*F12)+(Q12*R12))/AD12) -> N.A. | AD12: =+F12+R12 -> 0 | AF12: =IF(AG12=0,"N.A.",((H12*I12)+(T12*U12))/AG12) -> N.A. | AG12: =+I12+U12 -> 0 | AI12: =IF(AJ12=0,"N.A.",((B12*C12)+(N12*O12))/AJ12) -> N.A. | AJ12: =+C12+O12 -> 0 | AL12: =+AA12+AG12 -> 337.484 | AM12: =+AB12+AH12 -> 0 | AN12: =+AD12+AJ12 -> 0 | AO12: =+AE12+AK12 -> 0
A13: MARZO DE 2005 | W13: 11 | X13: 751.303 | Z13: =IF(AA13=0,"N.A.",((K13*L13)+(W13*X13))/AA13) -> 11 | AA13: =+L13+X13 -> 751.303 | AC13: =IF(AD13=0,"N.A.",((E13*F13)+(Q13*R13))/AD13) -> N.A. | AD13: =+F13+R13 -> 0 | AF13: =IF(AG13=0,"N.A.",((H13*I13)+(T13*U13))/AG13) -> N.A. | AG13: =+I13+U13 -> 0 | AI13: =IF(AJ13=0,"N.A.",((B13*C13)+(N13*O13))/AJ13) -> N.A. | AJ13: =+C13+O13 -> 0 | AL13: =+AA13+AG13 -> 751.303 | AM13: =+AB13+AH13 -> 0 | AN13: =+AD13+AJ13 -> 0 | AO13: =+AE13+AK13 -> 0
A14: ABRIL DE 2005 | W14: 11 | X14: 101.192 | Z14: =IF(AA14=0,"N.A.",((K14*L14)+(W14*X14))/AA14) -> 11 | AA14: =+L14+X14 -> 101.192 | AC14: =IF(AD14=0,"N.A.",((E14*F14)+(Q14*R14))/AD14) -> N.A. | AD14: =+F14+R14 -> 0 | AF14: =IF(AG14=0,"N.A.",((H14*I14)+(T14*U14))/AG14) -> N.A. | AG14: =+I14+U14 -> 0 | AI14: =IF(AJ14=0,"N.A.",((B14*C14)+(N14*O14))/AJ14) -> N.A. | AJ14: =+C14+O14 -> 0 | AL14: =+AA14+AG14 -> 101.192 | AM14: =+AB14+AH14 -> 0 | AN14: =+AD14+AJ14 -> 0 | AO14: =+AE14+AK14 -> 0
A15: MAYO DE 2005 | W15: 11 | X15: 323.619 | Z15: =IF(AA15=0,"N.A.",((K15*L15)+(W15*X15))/AA15) -> 11 | AA15: =+L15+X15 -> 323.619 | AC15: =IF(AD15=0,"N.A.",((E15*F15)+(Q15*R15))/AD15) -> N.A. | AD15: =+F15+R15 -> 0 | AF15: =IF(AG15=0,"N.A.",((H15*I15)+(T15*U15))/AG15) -> N.A. | AG15: =+I15+U15 -> 0 | AI15: =IF(AJ15=0,"N.A.",((B15*C15)+(N15*O15))/AJ15) -> N.A. | AJ15: =+C15+O15 -> 0 | AL15: =+AA15+AG15 -> 323.619 | AM15: =+AB15+AH15 -> 0 | AN15: =+AD15+AJ15 -> 0 | AO15: =+AE15+AK15 -> 0
A16: JUNIO DE 2005 | W16: 11 | X16: 100.18 | Z16: =IF(AA16=0,"N.A.",((K16*L16)+(W16*X16))/AA16) -> 11 | AA16: =+L16+X16 -> 100.18 | AC16: =IF(AD16=0,"N.A.",((E16*F16)+(Q16*R16))/AD16) -> N.A. | AD16: =+F16+R16 -> 0 | AF16: =IF(AG16=0,"N.A.",((H16*I16)+(T16*U16))/AG16) -> N.A. | AG16: =+I16+U16 -> 0 | AI16: =IF(AJ16=0,"N.A.",((B16*C16)+(N16*O16))/AJ16) -> N.A. | AJ16: =+C16+O16 -> 0 | AL16: =+AA16+AG16 -> 100.18 | AM16: =+AB16+AH16 -> 0 | AN16: =+AD16+AJ16 -> 0 | AO16: =+AE16+AK16 -> 0
A17: JULIO DE 2005 | W17: 11 | X17: 336.69 | Z17: =IF(AA17=0,"N.A.",((K17*L17)+(W17*X17))/AA17) -> 11 | AA17: =+L17+X17 -> 336.69 | AC17: =IF(AD17=0,"N.A.",((E17*F17)+(Q17*R17))/AD17) -> N.A. | AD17: =+F17+R17 -> 0 | AF17: =IF(AG17=0,"N.A.",((H17*I17)+(T17*U17))/AG17) -> N.A. | AG17: =+I17+U17 -> 0 | AI17: =IF(AJ17=0,"N.A.",((B17*C17)+(N17*O17))/AJ17) -> N.A. | AJ17: =+C17+O17 -> 0 | AL17: =+AA17+AG17 -> 336.69 | AM17: =+AB17+AH17 -> 0 | AN17: =+AD17+AJ17 -> 0 | AO17: =+AE17+AK17 -> 0
A18: AGOSTO DE 2005 | W18: 11 | X18: 401.286 | Z18: =IF(AA18=0,"N.A.",((K18*L18)+(W18*X18))/AA18) -> 11 | AA18: =+L18+X18 -> 401.286 | AC18: =IF(AD18=0,"N.A.",((E18*F18)+(Q18*R18))/AD18) -> N.A. | AD18: =+F18+R18 -> 0 | AF18: =IF(AG18=0,"N.A.",((H18*I18)+(T18*U18))/AG18) -> N.A. | AG18: =+I18+U18 -> 0 | AI18: =IF(AJ18=0,"N.A.",((B18*C18)+(N18*O18))/AJ18) -> N.A. | AJ18: =+C18+O18 -> 0 | AL18: =+AA18+AG18 -> 401.286 | AM18: =+AB18+AH18 -> 0 | AN18: =+AD18+AJ18 -> 0 | AO18: =+AE18+AK18 -> 0
... A34: DICIEMBRE DE 2006 | W34: 9 | X34: 355.106 | Z34: =IF(AA34=0,"N.A.",((K34*L34)+(W34*X34))/AA34) -> 9 | AA34: =+L34+X34 -> 355.106 | AC34: =IF(AD34=0,"N.A.",((E34*F34)+(Q34*R34))/AD34) -> N.A. | AD34: =+F34+R34 -> 0 | AF34: =IF(AG34=0,"N.A.",((H34*I34)+(T34*U34))/AG34) -> N.A. | AG34: =+I34+U34 -> 0 | AI34: =IF(AJ34=0,"N.A.",((B34*C34)+(N34*O34))/AJ34) -> N.A. | AJ34: =+C34+O34 -> 0 | AL34: =+AA34+AG34 -> 355.106 | AM34: =+AB34+AH34 -> 0 | AN34: =+AD34+AJ34 -> 0 | AO34: =+AE34+AK34 -> 0
A35: ENERO DE 2007 | N35: 12.68 | O35: 8.371 | W35: 9 | X35: 9.814 | Z35: =IF(AA35=0,"N.A.",((K35*L35)+(W35*X35))/AA35) -> 9 | AA35: =+L35+X35 -> 9.814 | AC35: =IF(AD35=0,"N.A.",((E35*F35)+(Q35*R35))/AD35) -> N.A. | AD35: =+F35+R35 -> 0 | AF35: =IF(AG35=0,"N.A.",((H35*I35)+(T35*U35))/AG35) -> N.A. | AG35: =+I35+U35 -> 0 | AI35: =IF(AJ35=0,"N.A.",((B35*C35)+(N35*O35))/AJ35) -> 12.68 | AJ35: =+C35+O35 -> 8.371 | AL35: =+AA35+AG35 -> 9.814 | AM35: =+AB35+AH35 -> 0 | AN35: =+AD35+AJ35 -> 8.371 | AO35: =+AE35+AK35 -> 0
A36: FEBRERO DE 2007 | N36: 12.68 | O36: 109.871 | W36: 9 | X36: 351.16 | Z36: =IF(AA36=0,"N.A.",((K36*L36)+(W36*X36))/AA36) -> 9 | AA36: =+L36+X36 -> 351.16 | AC36: =IF(AD36=0,"N.A.",((E36*F36)+(Q36*R36))/AD36) -> N.A. | AD36: =+F36+R36 -> 0 | AF36: =IF(AG36=0,"N.A.",((H36*I36)+(T36*U36))/AG36) -> N.A. | AG36: =+I36+U36 -> 0 | AI36: =IF(AJ36=0,"N.A.",((B36*C36)+(N36*O36))/AJ36) -> 12.68 | AJ36: =+C36+O36 -> 109.871 | AL36: =+AA36+AG36 -> 351.16 | AM36: =+AB36+AH36 -> 0 | AN36: =+AD36+AJ36 -> 109.871 | AO36: =+AE36+AK36 -> 0
A37: MARZO DE 2007 | N37: 12.68 | O37: 27.471 | W37: 9 | X37: 891.921 | Z37: =IF(AA37=0,"N.A.",((K37*L37)+(W37*X37))/AA37) -> 9 | AA37: =+L37+X37 -> 891.921 | AC37: =IF(AD37=0,"N.A.",((E37*F37)+(Q37*R37))/AD37) -> N.A. | AD37: =+F37+R37 -> 0 | AF37: =IF(AG37=0,"N.A.",((H37*I37)+(T37*U37))/AG37) -> N.A. | AG37: =+I37+U37 -> 0 | AI37: =IF(AJ37=0,"N.A.",((B37*C37)+(N37*O37))/AJ37) -> 12.68 | AJ37: =+C37+O37 -> 27.471 | AL37: =+AA37+AG37 -> 891.921 | AM37: =+AB37+AH37 -> 0 | AN37: =+AD37+AJ37 -> 27.471 | AO37: =+AE37+AK37 -> 0
A38: ABRIL DE 2007 | N38: 12.68 | O38: 13.593 | W38: 9 | X38: 82.729 | Z38: =IF(AA38=0,"N.A.",((K38*L38)+(W38*X38))/AA38) -> 9 | AA38: =+L38+X38 -> 82.729 | AC38: =IF(AD38=0,"N.A.",((E38*F38)+(Q38*R38))/AD38) -> N.A. | AD38: =+F38+R38 -> 0 | AF38: =IF(AG38=0,"N.A.",((H38*I38)+(T38*U38))/AG38) -> N.A. | AG38: =+I38+U38 -> 0 | AI38: =IF(AJ38=0,"N.A.",((B38*C38)+(N38*O38))/AJ38) -> 12.68 | AJ38: =+C38+O38 -> 13.593 | AL38: =+AA38+AG38 -> 82.729 | AM38: =+AB38+AH38 -> 0 | AN38: =+AD38+AJ38 -> 13.593 | AO38: =+AE38+AK38 -> 0
A39: MAYO DE 2007 | N39: 12.68 | O39: 14.476 | W39: 9 | X39: 148.171 | Z39: =IF(AA39=0,"N.A.",((K39*L39)+(W39*X39))/AA39) -> 9 | AA39: =+L39+X39 -> 148.171 | AC39: =IF(AD39=0,"N.A.",((E39*F39)+(Q39*R39))/AD39) -> N.A. | AD39: =+F39+R39 -> 0 | AF39: =IF(AG39=0,"N.A.",((H39*I39)+(T39*U39))/AG39) -> N.A. | AG39: =+I39+U39 -> 0 | AI39: =IF(AJ39=0,"N.A.",((B39*C39)+(N39*O39))/AJ39) -> 12.68 | AJ39: =+C39+O39 -> 14.476 | AL39: =+AA39+AG39 -> 148.171 | AM39: =+AB39+AH39 -> 0 | AN39: =+AD39+AJ39 -> 14.476 | AO39: =+AE39+AK39 -> 0
A40: JUNIO DE 2007 | N40: 15.28 | O40: 667.28 | W40: 9 | X40: 579.851 | Z40: =IF(AA40=0,"N.A.",((K40*L40)+(W40*X40))/AA40) -> 9 | AA40: =+L40+X40 -> 579.851 | AC40: =IF(AD40=0,"N.A.",((E40*F40)+(Q40*R40))/AD40) -> N.A. | AD40: =+F40+R40 -> 0 | AF40: =IF(AG40=0,"N.A.",((H40*I40)+(T40*U40))/AG40) -> N.A. | AG40: =+I40+U40 -> 0 | AI40: =IF(AJ40=0,"N.A.",((B40*C40)+(N40*O40))/AJ40) -> 15.28 | AJ40: =+C40+O40 -> 667.28 | AL40: =+AA40+AG40 -> 579.851 | AM40: =+AB40+AH40 -> 0 | AN40: =+AD40+AJ40 -> 667.28 | AO40: =+AE40+AK40 -> 0
A41: JULIO DE 2007 | N41: 18.15 | O41: 97.142 | W41: 9 | X41: 566.425 | Z41: =IF(AA41=0,"N.A.",((K41*L41)+(W41*X41))/AA41) -> 9 | AA41: =+L41+X41 -> 566.425 | AC41: =IF(AD41=0,"N.A.",((E41*F41)+(Q41*R41))/AD41) -> N.A. | AD41: =+F41+R41 -> 0 | AF41: =IF(AG41=0,"N.A.",((H41*I41)+(T41*U41))/AG41) -> N.A. | AG41: =+I41+U41 -> 0 | AI41: =IF(AJ41=0,"N.A.",((B41*C41)+(N41*O41))/AJ41) -> 18.15 | AJ41: =+C41+O41 -> 97.142 | AL41: =+AA41+AG41 -> 566.425 | AM41: =+AB41+AH41 -> 0 | AN41: =+AD41+AJ41 -> 97.142 | AO41: =+AE41+AK41 -> 0
A42: AGOSTO DE 2007 | N42: 14.69 | O42: 42.241 | W42: 9 | X42: 60.081 | Z42: =IF(AA42=0,"N.A.",((K42*L42)+(W42*X42))/AA42) -> 9 | AA42: =+L42+X42 -> 60.081 | AC42: =IF(AD42=0,"N.A.",((E42*F42)+(Q42*R42))/AD42) -> N.A. | AD42: =+F42+R42 -> 0 | AF42: =IF(AG42=0,"N.A.",((H42*I42)+(T42*U42))/AG42) -> N.A. | AG42: =+I42+U42 -> 0 | AI42: =IF(AJ42=0,"N.A.",((B42*C42)+(N42*O42))/AJ42) -> 14.69 | AJ42: =+C42+O42 -> 42.241 | AL42: =+AA42+AG42 -> 60.081 | AM42: =+AB42+AH42 -> 0 | AN42: =+AD42+AJ42 -> 42.241 | AO42: =+AE42+AK42 -> 0
A43: SEPTIEMBRE DE 2007 | O43: 0 | W43: 9 | X43: 153.529 | Z43: =IF(AA43=0,"N.A.",((K43*L43)+(W43*X43))/AA43) -> 9 | AA43: =+L43+X43 -> 153.529 | AC43: =IF(AD43=0,"N.A.",((E43*F43)+(Q43*R43))/AD43) -> N.A. | AD43: =+F43+R43 -> 0 | AF43: =IF(AG43=0,"N.A.",((H43*I43)+(T43*U43))/AG43) -> N.A. | AG43: =+I43+U43 -> 0 | AI43: =IF(AJ43=0,"N.A.",((B43*C43)+(N43*O43))/AJ43) -> N.A. | AJ43: =+C43+O43 -> 0 | AL43: =+AA43+AG43 -> 153.529 | AM43: =+AB43+AH43 -> 0 | AN43: =+AD43+AJ43 -> 0 | AO43: =+AE43+AK43 -> 0
A44: OCTUBRE DE 2007 | N44: 15.33 | O44: 60.691 | W44: 9 | X44: 93.384 | Z44: =IF(AA44=0,"N.A.",((K44*L44)+(W44*X44))/AA44) -> 9 | AA44: =+L44+X44 -> 93.384 | AC44: =IF(AD44=0,"N.A.",((E44*F44)+(Q44*R44))/AD44) -> N.A. | AD44: =+F44+R44 -> 0 | AF44: =IF(AG44=0,"N.A.",((H44*I44)+(T44*U44))/AG44) -> N.A. | AG44: =+I44+U44 -> 0 | AI44: =IF(AJ44=0,"N.A.",((B44*C44)+(N44*O44))/AJ44) -> 15.33 | AJ44: =+C44+O44 -> 60.691 | AL44: =+AA44+AG44 -> 93.384 | AM44: =+AB44+AH44 -> 0 | AN44: =+AD44+AJ44 -> 60.691 | AO44: =+AE44+AK44 -> 0
A45: NOVIEMBRE DE 2007 | W45: 9 | X45: 9.28 | Z45: =IF(AA45=0,"N.A.",((K45*L45)+(W45*X45))/AA45) -> 9 | AA45: =+L45+X45 -> 9.28 | AC45: =IF(AD45=0,"N.A.",((E45*F45)+(Q45*R45))/AD45) -> N.A. | AD45: =+F45+R45 -> 0 | AF45: =IF(AG45=0,"N.A.",((H45*I45)+(T45*U45))/AG45) -> N.A. | AG45: =+I45+U45 -> 0 | AI45: =IF(AJ45=0,"N.A.",((B45*C45)+(N45*O45))/AJ45) -> N.A. | AJ45: =+C45+O45 -> 0 | AL45: =+AA45+AG45 -> 9.28 | AM45: =+AB45+AH45 -> 0 | AN45: =+AD45+AJ45 -> 0 | AO45: =+AE45+AK45 -> 0
A46: DICIEMBRE DE 2007 | X46: 0 | Z46: =IF(AA46=0,"N.A.",((K46*L46)+(W46*X46))/AA46) -> N.A. | AA46: =+L46+X46 -> 0 | AC46: =IF(AD46=0,"N.A.",((E46*F46)+(Q46*R46))/AD46) -> N.A. | AD46: =+F46+R46 -> 0 | AF46: =IF(AG46=0,"N.A.",((H46*I46)+(T46*U46))/AG46) -> N.A. | AG46: =+I46+U46 -> 0 | AI46: =IF(AJ46=0,"N.A.",((B46*C46)+(N46*O46))/AJ46) -> N.A. | AJ46: =+C46+O46 -> 0 | AL46: =+AA46+AG46 -> 0 | AM46: =+AB46+AH46 -> 0 | AN46: =+AD46+AJ46 -> 0 | AO46: =+AE46+AK46 -> 0
A47: ENERO DE 2008 | X47: 0 | Z47: =IF(AA47=0,"N.A.",((K47*L47)+(W47*X47))/AA47) -> N.A. | AA47: =+L47+X47 -> 0 | AC47: =IF(AD47=0,"N.A.",((E47*F47)+(Q47*R47))/AD47) -> N.A. | AD47: =+F47+R47 -> 0 | AF47: =IF(AG47=0,"N.A.",((H47*I47)+(T47*U47))/AG47) -> N.A. | AG47: =+I47+U47 -> 0 | AI47: =IF(AJ47=0,"N.A.",((B47*C47)+(N47*O47))/AJ47) -> N.A. | AJ47: =+C47+O47 -> 0 | AL47: =+AA47+AG47 -> 0 | AM47: =+AB47+AH47 -> 0 | AN47: =+AD47+AJ47 -> 0 | AO47: =+AE47+AK47 -> 0
A48: FEBRERO DE 2008 | X48: 0 | Z48: =IF(AA48=0,"N.A.",((K48*L48)+(W48*X48))/AA48) -> N.A. | AA48: =+L48+X48 -> 0 | AC48: =IF(AD48=0,"N.A.",((E48*F48)+(Q48*R48))/AD48) -> N.A. | AD48: =+F48+R48 -> 0 | AF48: =IF(AG48=0,"N.A.",((H48*I48)+(T48*U48))/AG48) -> N.A. | AG48: =+I48+U48 -> 0 | AI48: =IF(AJ48=0,"N.A.",((B48*C48)+(N48*O48))/AJ48) -> N.A. | AJ48: =+C48+O48 -> 0 | AL48: =+AA48+AG48 -> 0 | AM48: =+AB48+AH48 -> 0 | AN48: =+AD48+AJ48 -> 0 | AO48: =+AE48+AK48 -> 0
A49: MARZO DE 2008 | W49: 9 | X49: 301.438 | Z49: =IF(AA49=0,"N.A.",((K49*L49)+(W49*X49))/AA49) -> 9 | AA49: =+L49+X49 -> 301.438 | AC49: =IF(AD49=0,"N.A.",((E49*F49)+(Q49*R49))/AD49) -> N.A. | AD49: =+F49+R49 -> 0 | AF49: =IF(AG49=0,"N.A.",((H49*I49)+(T49*U49))/AG49) -> N.A. | AG49: =+I49+U49 -> 0 | AI49: =IF(AJ49=0,"N.A.",((B49*C49)+(N49*O49))/AJ49) -> N.A. | AJ49: =+C49+O49 -> 0 | AL49: =+AA49+AG49 -> 301.438 | AM49: =+AB49+AH49 -> 0 | AN49: =+AD49+AJ49 -> 0 | AO49: =+AE49+AK49 -> 0
A50: ABRIL DE 2008 | Q50: 9 | R50: 228.993 | W50: 9 | X50: 706.569 | Z50: =IF(AA50=0,"N.A.",((K50*L50)+(W50*X50))/AA50) -> 9 | AA50: =+L50+X50 -> 706.569 | AC50: =IF(AD50=0,"N.A.",((E50*F50)+(Q50*R50))/AD50) -> 9 | AD50: =+F50+R50 -> 228.993 | AF50: =IF(AG50=0,"N.A.",((H50*I50)+(T50*U50))/AG50) -> N.A. | AG50: =+I50+U50 -> 0 | AI50: =IF(AJ50=0,"N.A.",((B50*C50)+(N50*O50))/AJ50) -> N.A. | AJ50: =+C50+O50 -> 0 | AL50: =+AA50+AG50 -> 706.569 | AM50: =+AB50+AH50 -> 0 | AN50: =+AD50+AJ50 -> 228.993 | AO50: =+AE50+AK50 -> 0
A51: MAYO DE 2008 | N51: 14 | O51: 103.83 | Q51: 9 | R51: 105 | W51: 9 | X51: 87.015 | Z51: =IF(AA51=0,"N.A.",((K51*L51)+(W51*X51))/AA51) -> 9 | AA51: =+L51+X51 -> 87.015 | AC51: =IF(AD51=0,"N.A.",((E51*F51)+(Q51*R51))/AD51) -> 9 | AD51: =+F51+R51 -> 105 | AF51: =IF(AG51=0,"N.A.",((H51*I51)+(T51*U51))/AG51) -> N.A. | AG51: =+I51+U51 -> 0 | AI51: =IF(AJ51=0,"N.A.",((B51*C51)+(N51*O51))/AJ51) -> 14 | AJ51: =+C51+O51 -> 103.83 | AL51: =+AA51+AG51 -> 87.015 | AM51: =+AB51+AH51 -> 0 | AN51: =+AD51+AJ51 -> 208.83 | AO51: =+AE51+AK51 -> 0
A52: JUNIO DE 2008 | O52: 0 | R52: 0 | W52: 9 | X52: 41.715 | Z52: =IF(AA52=0,"N.A.",((K52*L52)+(W52*X52))/AA52) -> 9 | AA52: =+L52+X52 -> 41.715 | AC52: =IF(AD52=0,"N.A.",((E52*F52)+(Q52*R52))/AD52) -> N.A. | AD52: =+F52+R52 -> 0 | AF52: =IF(AG52=0,"N.A.",((H52*I52)+(T52*U52))/AG52) -> N.A. | AG52: =+I52+U52 -> 0 | AI52: =IF(AJ52=0,"N.A.",((B52*C52)+(N52*O52))/AJ52) -> N.A. | AJ52: =+C52+O52 -> 0 | AL52: =+AA52+AG52 -> 41.715 | AM52: =+AB52+AH52 -> 0 | AN52: =+AD52+AJ52 -> 0 | AO52: =+AE52+AK52 -> 0
A53: JULIO DE 2008 | N53: 14 | O53: 155.011 | Q53: 9 | R53: 100.1 | W53: 9 | X53: 92.835 | Z53: =IF(AA53=0,"N.A.",((K53*L53)+(W53*X53))/AA53) -> 9 | AA53: =+L53+X53 -> 92.835 | AC53: =IF(AD53=0,"N.A.",((E53*F53)+(Q53*R53))/AD53) -> 9 | AD53: =+F53+R53 -> 100.1 | AF53: =IF(AG53=0,"N.A.",((H53*I53)+(T53*U53))/AG53) -> N.A. | AG53: =+I53+U53 -> 0 | AI53: =IF(AJ53=0,"N.A.",((B53*C53)+(N53*O53))/AJ53) -> 14 | AJ53: =+C53+O53 -> 155.011 | AL53: =+AA53+AG53 -> 92.835 | AM53: =+AB53+AH53 -> 0 | AN53: =+AD53+AJ53 -> 255.111 | AO53: =+AE53+AK53 -> 0
A54: AGOSTO DE 2008 | N54: 17.2 | O54: 230.5 | Q54: 9 | R54: 245.5 | W54: 9 | X54: 25.2 | Z54: =IF(AA54=0,"N.A.",((K54*L54)+(W54*X54))/AA54) -> 9 | AA54: =+L54+X54 -> 25.2 | AC54: =IF(AD54=0,"N.A.",((E54*F54)+(Q54*R54))/AD54) -> 9 | AD54: =+F54+R54 -> 245.5 | AF54: =IF(AG54=0,"N.A.",((H54*I54)+(T54*U54))/AG54) -> N.A. | AG54: =+I54+U54 -> 0 | AI54: =IF(AJ54=0,"N.A.",((B54*C54)+(N54*O54))/AJ54) -> 17.2 | AJ54: =+C54+O54 -> 230.5 | AL54: =+AA54+AG54 -> 25.2 | AM54: =+AB54+AH54 -> 0 | AN54: =+AD54+AJ54 -> 476 | AO54: =+AE54+AK54 -> 0
A55: SEPTIEMBRE DE 2008 | N55: 14.35 | O55: 776.989 | Q55: 9 | R55: 84.3 | X55: 0 | Z55: =IF(AA55=0,"N.A.",((K55*L55)+(W55*X55))/AA55) -> N.A. | AA55: =+L55+X55 -> 0 | AC55: =IF(AD55=0,"N.A.",((E55*F55)+(Q55*R55))/AD55) -> 9 | AD55: =+F55+R55 -> 84.3 | AF55: =IF(AG55=0,"N.A.",((H55*I55)+(T55*U55))/AG55) -> N.A. | AG55: =+I55+U55 -> 0 | AI55: =IF(AJ55=0,"N.A.",((B55*C55)+(N55*O55))/AJ55) -> 14.35 | AJ55: =+C55+O55 -> 776.989 | AL55: =+AA55+AG55 -> 0 | AM55: =+AB55+AH55 -> 0 | AN55: =+AD55+AJ55 -> 861.289 | AO55: =+AE55+AK55 -> 0
...

Sheet 2- popular
A1: TASAS Y DESEMBOLSOS MENSUALES DE CARTERA DE VIVIENDA
A2: BANCO POPULAR
AG3: Cifras en millones de pesos y tasas efectivas anuales promedio ponderadas
A4: MES | B4: Construcción de Vivienda diferente de VIS en pesos | E4: Construcción de Vivienda diferente de VIS en UVR | H4: Construcción de Vivienda VIS en pesos | K4: Construcción de Vivienda VIS en UVR | N4: Adquisición de Vivienda diferente de VIS en Pesos | Q4: Adquisición de Vivienda diferente de VIS en UVR | T4: Adquisición de Vivienda VIS en Pesos | W4: Adquisición de Vivienda VIS en UVR | Z4: CREDITOS DE VIVIENDA en U.V.R. (Puntos) | AF4: CREDITOS DE VIVIENDA en Pesos (T.E.A.) | AL4: CONSOLIDADO
Z5: VIS | AC5: NO VIS | AF5: VIS | AI5: NO VIS | AL5: VIS | AN5: NO VIS
B6: TASA | C6: MONTO | D6: NÚMERO DE CRÉDITOS DESEMBOLSADOS | E6: TASA | F6: MONTO | G6: NÚMERO DE CRÉDITOS DESEMBOLSADOS | H6: TASA | I6: MONTO | J6: NÚMERO DE CRÉDITOS DESEMBOLSADOS | K6: TASA | L6: MONTO | M6: NÚMERO DE CRÉDITOS DESEMBOLSADOS | N6: TASA | O6: MONTO | P6: NÚMERO DE CRÉDITOS DESEMBOLSADOS | Q6: TASA | R6: MONTO | S6: NÚMERO DE CRÉDITOS DESEMBOLSADOS | T6: TASA | U6: MONTO | V6: NÚMERO DE CRÉDITOS DESEMBOLSADOS | W6: TASA | X6: MONTO | Y6: NÚMERO DE CRÉDITOS DESEMBOLSADOS | Z6: TASA | AA6: MONTO | AB6: NÚMERO DE CRÉDITOS DESEMBOLSADOS | AC6: TASA | AD6: MONTO | AE6: NÚMERO DE CRÉDITOS DESEMBOLSADOS | AF6: TASA | AG6: MONTO | AH6: NÚMERO DE CRÉDITOS DESEMBOLSADOS | AI6: TASA | AJ6: MONTO | AK6: NÚMERO DE CRÉDITOS DESEMBOLSADOS | AL6: MONTO | AM6: NÚMERO DE CRÉDITOS DESEMBOLSADOS | AN6: MONTO | AO6: NÚMERO DE CRÉDITOS DESEMBOLSADOS
A7: MAYO DE 2002 | K7: 11 | L7: 32.68 | N7: 16.8 | O7: 131 | W7: 11 | X7: 66.81 | Z7: =IF(AA7=0,"N.A.",((K7*L7)+(W7*X7))/AA7) -> 11 | AA7: =+L7+X7 -> 99.49 | AC7: =IF(AD7=0,"N.A.",((E7*F7)+(Q7*R7))/AD7) -> N.A. | AD7: =+F7+R7 -> 0 | AF7: =IF(AG7=0,"N.A.",((H7*I7)+(T7*U7))/AG7) -> N.A. | AG7: =+I7+U7 -> 0 | AI7: =IF(AJ7=0,"N.A.",((B7*C7)+(N7*O7))/AJ7) -> 16.8 | AJ7: =+C7+O7 -> 131 | AL7: =+AA7+AG7 -> 99.49 | AM7: =+AB7+AH7 -> 0 | AN7: =+AD7+AJ7 -> 131 | AO7: =+AE7+AK7 -> 0
A8: JUNIO DE 2002 | N8: 16.8 | O8: 238.998 | Q8: 13.91 | R8: 82 | U8: 0 | X8: 0 | Z8: =IF(AA8=0,"N.A.",((K8*L8)+(W8*X8))/AA8) -> N.A. | AA8: =+L8+X8 -> 0 | AC8: =IF(AD8=0,"N.A.",((E8*F8)+(Q8*R8))/AD8) -> 13.91 | AD8: =+F8+R8 -> 82 | AF8: =IF(AG8=0,"N.A.",((H8*I8)+(T8*U8))/AG8) -> N.A. | AG8: =+I8+U8 -> 0 | AI8: =IF(AJ8=0,"N.A.",((B8*C8)+(N8*O8))/AJ8) -> 16.8 | AJ8: =+C8+O8 -> 238.998 | AL8: =+AA8+AG8 -> 0 | AM8: =+AB8+AH8 -> 0 | AN8: =+AD8+AJ8 -> 320.998 | AO8: =+AE8+AK8 -> 0
A9: JULIO DE 2002 | N9: 16.15 | O9: 251 | R9: 0 | T9: 16.28 | U9: 30.8 | X9: 0 | Z9: =IF(AA9=0,"N.A.",((K9*L9)+(W9*X9))/AA9) -> N.A. | AA9: =+L9+X9 -> 0 | AC9: =IF(AD9=0,"N.A.",((E9*F9)+(Q9*R9))/AD9) -> N.A. | AD9: =+F9+R9 -> 0 | AF9: =IF(AG9=0,"N.A.",((H9*I9)+(T9*U9))/AG9) -> 16.28 | AG9: =+I9+U9 -> 30.8 | AI9: =IF(AJ9=0,"N.A.",((B9*C9)+(N9*O9))/AJ9) -> 16.15 | AJ9: =+C9+O9 -> 251 | AL9: =+AA9+AG9 -> 30.8 | AM9: =+AB9+AH9 -> 0 | AN9: =+AD9+AJ9 -> 251 | AO9: =+AE9+AK9 -> 0
A10: AGOSTO DE 2002 | N10: 16.703077 | O10: 291.2 | Q10: 13.818894 | R10: 364.519 | T10: 16.348309 | U10: 95.8 | W10: 11 | X10: 52.959 | Z10: =IF(AA10=0,"N.A.",((K10*L10)+(W10*X10))/AA10) -> 11 | AA10: =+L10+X10 -> 52.959 | AC10: =IF(AD10=0,"N.A.",((E10*F10)+(Q10*R10))/AD10) -> 13.818894 | AD10: =+F10+R10 -> 364.519 | AF10: =IF(AG10=0,"N.A.",((H10*I10)+(T10*U10))/AG10) -> 16.348309 | AG10: =+I10+U10 -> 95.8 | AI10: =IF(AJ10=0,"N.A.",((B10*C10)+(N10*O10))/AJ10) -> 16.703077 | AJ10: =+C10+O10 -> 291.2 | AL10: =+AA10+AG10 -> 148.759 | AM10: =+AB10+AH10 -> 0 | AN10: =+AD10+AJ10 -> 655.719 | AO10: =+AE10+AK10 -> 0
A11: SEPTIEMBRE DE 2002 | N11: 16.08 | O11: 56.25 | Q11: 13.91 | R11: 30 | T11: 16.08 | U11: 164.2 | W11: 11 | X11: 10 | Z11: =IF(AA11=0,"N.A.",((K11*L11)+(W11*X11))/AA11) -> 11 | AA11: =+L11+X11 -> 10 | AC11: =IF(AD11=0,"N.A.",((E11*F11)+(Q11*R11))/AD11) -> 13.91 | AD11: =+F11+R11 -> 30 | AF11: =IF(AG11=0,"N.A.",((H11*I11)+(T11*U11))/AG11) -> 16.08 | AG11: =+I11+U11 -> 164.2 | AI11: =IF(AJ11=0,"N.A.",((B11*C11)+(N11*O11))/AJ11) -> 16.08 | AJ11: =+C11+O11 -> 56.25 | AL11: =+AA11+AG11 -> 174.2 | AM11: =+AB11+AH11 -> 0 | AN11: =+AD11+AJ11 -> 86.25 | AO11: =+AE11+AK11 -> 0
A12: OCTUBRE DE 2002 | O12: 0 | R12: 0 | T12: 16.08 | U12: 16 | X12: 0 | Z12: =IF(AA12=0,"N.A.",((K12*L12)+(W12*X12))/AA12) -> N.A. | AA12: =+L12+X12 -> 0 | AC12: =IF(AD12=0,"N.A.",((E12*F12)+(Q12*R12))/AD12) -> N.A. | AD12: =+F12+R12 -> 0 | AF12: =IF(AG12=0,"N.A.",((H12*I12)+(T12*U12))/AG12) -> 16.08 | AG12: =+I12+U12 -> 16 | AI12: =IF(AJ12=0,"N.A.",((B12*C12)+(N12*O12))/AJ12) -> N.A. | AJ12: =+C12+O12 -> 0 | AL12: =+AA12+AG12 -> 16 | AM12: =+AB12+AH12 -> 0 | AN12: =+AD12+AJ12 -> 0 | AO12: =+AE12+AK12 -> 0
A13: NOVIEMBRE DE 2002 | N13: 16.08 | O13: 30 | R13: 0 | T13: 16.08 | U13: 61.25 | W13: 11 | X13: 70.582 | Z13: =IF(AA13=0,"N.A.",((K13*L13)+(W13*X13))/AA13) -> 11 | AA13: =+L13+X13 -> 70.582 | AC13: =IF(AD13=0,"N.A.",((E13*F13)+(Q13*R13))/AD13) -> N.A. | AD13: =+F13+R13 -> 0 | AF13: =IF(AG13=0,"N.A.",((H13*I13)+(T13*U13))/AG13) -> 16.08 | AG13: =+I13+U13 -> 61.25 | AI13: =IF(AJ13=0,"N.A.",((B13*C13)+(N13*O13))/AJ13) -> 16.08 | AJ13: =+C13+O13 -> 30 | AL13: =+AA13+AG13 -> 131.832 | AM13: =+AB13+AH13 -> 0 | AN13: =+AD13+AJ13 -> 30 | AO13: =+AE13+AK13 -> 0
A14: DICIEMBRE DE 2002 | N14: 16.08 | O14: 95.4 | R14: 0 | T14: 16.08 | U14: 67.7 | W14: 11 | X14: 176.092 | Z14: =IF(AA14=0,"N.A.",((K14*L14)+(W14*X14))/AA14) -> 11 | AA14: =+L14+X14 -> 176.092 | AC14: =IF(AD14=0,"N.A.",((E14*F14)+(Q14*R14))/AD14) -> N.A. | AD14: =+F14+R14 -> 0 | AF14: =IF(AG14=0,"N.A.",((H14*I14)+(T14*U14))/AG14) -> 16.08 | AG14: =+I14+U14 -> 67.7 | AI14: =IF(AJ14=0,"N.A.",((B14*C14)+(N14*O14))/AJ14) -> 16.08 | AJ14: =+C14+O14 -> 95.4 | AL14: =+AA14+AG14 -> 243.792 | AM14: =+AB14+AH14 -> 0 | AN14: =+AD14+AJ14 -> 95.4 | AO14: =+AE14+AK14 -> 0
A15: ENERO DE 2003 | O15: 0 | R15: 0 | T15: 16.08 | U15: 49 | W15: 11 | X15: 31.2 | Z15: =IF(AA15=0,"N.A.",((K15*L15)+(W15*X15))/AA15) -> 11 | AA15: =+L15+X15 -> 31.2 | AC15: =IF(AD15=0,"N.A.",((E15*F15)+(Q15*R15))/AD15) -> N.A. | AD15: =+F15+R15 -> 0 | AF15: =IF(AG15=0,"N.A.",((H15*I15)+(T15*U15))/AG15) -> 16.08 | AG15: =+I15+U15 -> 49 | AI15: =IF(AJ15=0,"N.A.",((B15*C15)+(N15*O15))/AJ15) -> N.A. | AJ15: =+C15+O15 -> 0 | AL15: =+AA15+AG15 -> 80.2 | AM15: =+AB15+AH15 -> 0 | AN15: =+AD15+AJ15 -> 0 | AO15: =+AE15+AK15 -> 0
A16: FEBRERO DE 2003 | O16: 0 | Q16: 13.9 | R16: 582.898 | U16: 0 | W16: 11 | X16: 11.725 | Z16: =IF(AA16=0,"N.A.",((K16*L16)+(W16*X16))/AA16) -> 11 | AA16: =+L16+X16 -> 11.725 | AC16: =IF(AD16=0,"N.A.",((E16*F16)+(Q16*R16))/AD16) -> 13.9 | AD16: =+F16+R16 -> 582.898 | AF16: =IF(AG16=0,"N.A.",((H16*I16)+(T16*U16))/AG16) -> N.A. | AG16: =+I16+U16 -> 0 | AI16: =IF(AJ16=0,"N.A.",((B16*C16)+(N16*O16))/AJ16) -> N.A. | AJ16: =+C16+O16 -> 0 | AL16: =+AA16+AG16 -> 11.725 | AM16: =+AB16+AH16 -> 0 | AN16: =+AD16+AJ16 -> 582.898 | AO16: =+AE16+AK16 -> 0
A17: MARZO DE 2003 | O17: 0 | R17: 0 | T17: 16.08 | U17: 149.4 | W17: 11 | X17: 46.017 | Z17: =IF(AA17=0,"N.A.",((K17*L17)+(W17*X17))/AA17) -> 11 | AA17: =+L17+X17 -> 46.017 | AC17: =IF(AD17=0,"N.A.",((E17*F17)+(Q17*R17))/AD17) -> N.A. | AD17: =+F17+R17 -> 0 | AF17: =IF(AG17=0,"N.A.",((H17*I17)+(T17*U17))/AG17) -> 16.08 | AG17: =+I17+U17 -> 149.4 | AI17: =IF(AJ17=0,"N.A.",((B17*C17)+(N17*O17))/AJ17) -> N.A. | AJ17: =+C17+O17 -> 0 | AL17: =+AA17+AG17 -> 195.417 | AM17: =+AB17+AH17 -> 0 | AN17: =+AD17+AJ17 -> 0 | AO17: =+AE17+AK17 -> 0
A18: ABRIL DE 2003 | O18: 0 | R18: 0 | T18: 16.08 | U18: 56.65 | X18: 0 | Z18: =IF(AA18=0,"N.A.",((K18*L18)+(W18*X18))/AA18) -> N.A. | AA18: =+L18+X18 -> 0 | AC18: =IF(AD18=0,"N.A.",((E18*F18)+(Q18*R18))/AD18) -> N.A. | AD18: =+F18+R18 -> 0 | AF18: =IF(AG18=0,"N.A.",((H18*I18)+(T18*U18))/AG18) -> 16.08 | AG18: =+I18+U18 -> 56.65 | AI18: =IF(AJ18=0,"N.A.",((B18*C18)+(N18*O18))/AJ18) -> N.A. | AJ18: =+C18+O18 -> 0 | AL18: =+AA18+AG18 -> 56.65 | AM18: =+AB18+AH18 -> 0 | AN18: =+AD18+AJ18 -> 0 | AO18: =+AE18+AK18 -> 0
A19: MAYO DE 2003 | N19: 16.08 | O19: 194.4 | R19: 0 | T19: 16.08 | U19: 53.4 | W19: 11 | X19: 67.083 | Z19: =IF(AA19=0,"N.A.",((K19*L19)+(W19*X19))/AA19) -> 11 | AA19: =+L19+X19 -> 67.083 | AC19: =IF(AD19=0,"N.A.",((E19*F19)+(Q19*R19))/AD19) -> N.A. | AD19: =+F19+R19 -> 0 | AF19: =IF(AG19=0,"N.A.",((H19*I19)+(T19*U19))/AG19) -> 16.08 | AG19: =+I19+U19 -> 53.4 | AI19: =IF(AJ19=0,"N.A.",((B19*C19)+(N19*O19))/AJ19) -> 16.08 | AJ19: =+C19+O19 -> 194.4 | AL19: =+AA19+AG19 -> 120.483 | AM19: =+AB19+AH19 -> 0 | AN19: =+AD19+AJ19 -> 194.4 | AO19: =+AE19+AK19 -> 0
A20: JUNIO DE 2003 | O20: 0 | Q20: 13.91 | R20: 41.4 | T20: 16.08 | U20: 53.5 | W20: 11 | X20: 45.199 | Z20: =IF(AA20=0,"N.A.",((K20*L20)+(W20*X20))/AA20) -> 11 | AA20: =+L20+X20 -> 45.199 | AC20: =IF(AD20=0,"N.A.",((E20*F20)+(Q20*R20))/AD20) -> 13.91 | AD20: =+F20+R20 -> 41.4 | AF20: =IF(AG20=0,"N.A.",((H20*I20)+(T20*U20))/AG20) -> 16.08 | AG20: =+I20+U20 -> 53.5 | AI20: =IF(AJ20=0,"N.A.",((B20*C20)+(N20*O20))/AJ20) -> N.A. | AJ20: =+C20+O20 -> 0 | AL20: =+AA20+AG20 -> 98.699 | AM20: =+AB20+AH20 -> 0 | AN20: =+AD20+AJ20 -> 41.4 | AO20: =+AE20+AK20 -> 0
A21: JULIO DE 2002 | N21: 16.08 | O21: 168.04 | Q21: 13.91 | R21: 36.3 | T21: 16.08 | U21: 97.9 | X21: 0 | Z21: =IF(AA21=0,"N.A.",((K21*L21)+(W21*X21))/AA21) -> N.A. | AA21: =+L21+X21 -> 0 | AC21: =IF(AD21=0,"N.A.",((E21*F21)+(Q21*R21))/AD21) -> 13.91 | AD21: =+F21+R21 -> 36.3 | AF21: =IF(AG21=0,"N.A.",((H21*I21)+(T21*U21))/AG21) -> 16.08 | AG21: =+I21+U21 -> 97.9 | AI21: =IF(AJ21=0,"N.A.",((B21*C21)+(N21*O21))/AJ21) -> 16.08 | AJ21: =+C21+O21 -> 168.04 | AL21: =+AA21+AG21 -> 97.9 | AM21: =+AB21+AH21 -> 0 | AN21: =+AD21+AJ21 -> 204.34 | AO21: =+AE21+AK21 -> 0
A22: AGOSTO DE 2003 | O22: 0 | R22: 0 | T22: 16.08 | U22: 35.7 | X22: 0 | Z22: =IF(AA22=0,"N.A.",((K22*L22)+(W22*X22))/AA22) -> N.A. | AA22: =+L22+X22 -> 0 | AC22: =IF(AD22=0,"N.A.",((E22*F22)+(Q22*R22))/AD22) -> N.A. | AD22: =+F22+R22 -> 0 | AF22: =IF(AG22=0,"N.A.",((H22*I22)+(T22*U22))/AG22) -> 16.08 | AG22: =+I22+U22 -> 35.7 | AI22: =IF(AJ22=0,"N.A.",((B22*C22)+(N22*O22))/AJ22) -> N.A. | AJ22: =+C22+O22 -> 0 | AL22: =+AA22+AG22 -> 35.7 | AM22: =+AB22+AH22 -> 0 | AN22: =+AD22+AJ22 -> 0 | AO22: =+AE22+AK22 -> 0
A23: SEPTIEMBRE DE 2003 | N23: 16.08 | O23: 151.9 | Q23: 13.91 | R23: 29 | T23: 16.08 | U23: 186.35 | W23: 11 | X23: 14 | Z23: =IF(AA23=0,"N.A.",((K23*L23)+(W23*X23))/AA23) -> 11 | AA23: =+L23+X23 -> 14 | AC23: =IF(AD23=0,"N.A.",((E23*F23)+(Q23*R23))/AD23) -> 13.91 | AD23: =+F23+R23 -> 29 | AF23: =IF(AG23=0,"N.A.",((H23*I23)+(T23*U23))/AG23) -> 16.08 | AG23: =+I23+U23 -> 186.35 | AI23: =IF(AJ23=0,"N.A.",((B23*C23)+(N23*O23))/AJ23) -> 16.08 | AJ23: =+C23+O23 -> 151.9 | AL23: =+AA23+AG23 -> 200.35 | AM23: =+AB23+AH23 -> 0 | AN23: =+AD23+AJ23 -> 180.9 | AO23: =+AE23+AK23 -> 0
A24: OCTUBRE DE 2003 | N24: 16.08 | O24: 150.5 | R24: 0 | T24: 16.08 | U24: 60.846 | W24: 11 | X24: 10.942 | Z24: =IF(AA24=0,"N.A.",((K24*L24)+(W24*X24))/AA24) -> 11 | AA24: =+L24+X24 -> 10.942 | AC24: =IF(AD24=0,"N.A.",((E24*F24)+(Q24*R24))/AD24) -> N.A. | AD24: =+F24+R24 -> 0 | AF24: =IF(AG24=0,"N.A.",((H24*I24)+(T24*U24))/AG24) -> 16.08 | AG24: =+I24+U24 -> 60.846 | AI24: =IF(AJ24=0,"N.A.",((B24*C24)+(N24*O24))/AJ24) -> 16.08 | AJ24: =+C24+O24 -> 150.5 | AL24: =+AA24+AG24 -> 71.788 | AM24: =+AB24+AH24 -> 0 | AN24: =+AD24+AJ24 -> 150.5 | AO24: =+AE24+AK24 -> 0
A25: NOVIEMBRE DE 2003 | O25: 0 | R25: 0 | T25: 16.08 | U25: 334.306 | W25: 11 | X25: 10 | Z25: =IF(AA25=0,"N.A.",((K25*L25)+(W25*X25))/AA25) -> 11 | AA25: =+L25+X25 -> 10 | AC25: =IF(AD25=0,"N.A.",((E25*F25)+(Q25*R25))/AD25) -> N.A. | AD25: =+F25+R25 -> 0 | AF25: =IF(AG25=0,"N.A.",((H25*I25)+(T25*U25))/AG25) -> 16.08 | AG25: =+I25+U25 -> 334.306 | AI25: =IF(AJ25=0,"N.A.",((B25*C25)+(N25*O25))/AJ25) -> N.A. | AJ25: =+C25+O25 -> 0 | AL25: =+AA25+AG25 -> 344.306 | AM25: =+AB25+AH25 -> 0 | AN25: =+AD25+AJ25 -> 0 | AO25: =+AE25+AK25 -> 0
A26: DICIEMBRE DE 2003 | N26: 16.08 | O26: 54.25 | R26: 0 | T26: 16.08 | U26: 71.9 | X26: 0 | Z26: =IF(AA26=0,"N.A.",((K26*L26)+(W26*X26))/AA26) -> N.A. | AA26: =+L26+X26 -> 0 | AC26: =IF(AD26=0,"N.A.",((E26*F26)+(Q26*R26))/AD26) -> N.A. | AD26: =+F26+R26 -> 0 | AF26: =IF(AG26=0,"N.A.",((H26*I26)+(T26*U26))/AG26) -> 16.08 | AG26: =+I26+U26 -> 71.9 | AI26: =IF(AJ26=0,"N.A.",((B26*C26)+(N26*O26))/AJ26) -> 16.08 | AJ26: =+C26+O26 -> 54.25 | AL26: =+AA26+AG26 -> 71.9 | AM26: =+AB26+AH26 -> 0 | AN26: =+AD26+AJ26 -> 54.25 | AO26: =+AE26+AK26 -> 0
A27: ENERO DE 2004 | N27: 16.08 | O27: 62 | R27: 0 | T27: 16.08 | U27: 167.65 | W27: 11 | X27: 20 | Z27: =IF(AA27=0,"N.A.",((K27*L27)+(W27*X27))/AA27) -> 11 | AA27: =+L27+X27 -> 20 | AC27: =IF(AD27=0,"N.A.",((E27*F27)+(Q27*R27))/AD27) -> N.A. | AD27: =+F27+R27 -> 0 | AF27: =IF(AG27=0,"N.A.",((H27*I27)+(T27*U27))/AG27) -> 16.08 | AG27: =+I27+U27 -> 167.65 | AI27: =IF(AJ27=0,"N.A.",((B27*C27)+(N27*O27))/AJ27) -> 16.08 | AJ27: =+C27+O27 -> 62 | AL27: =+AA27+AG27 -> 187.65 | AM27: =+AB27+AH27 -> 0 | AN27: =+AD27+AJ27 -> 62 | AO27: =+AE27+AK27 -> 0
A28: FEBRERO DE 2004 | N28: 16.08 | O28: 18.3 | R28: 0 | T28: 16.08 | U28: 59.05 | W28: 11 | X28: 19.6 | Z28: =IF(AA28=0,"N.A.",((K28*L28)+(W28*X28))/AA28) -> 11 | AA28: =+L28+X28 -> 19.6 | AC28: =IF(AD28=0,"N.A.",((E28*F28)+(Q28*R28))/AD28) -> N.A. | AD28: =+F28+R28 -> 0 | AF28: =IF(AG28=0,"N.A.",((H28*I28)+(T28*U28))/AG28) -> 16.08 | AG28: =+I28+U28 -> 59.05 | AI28: =IF(AJ28=0,"N.A.",((B28*C28)+(N28*O28))/AJ28) -> 16.08 | AJ28: =+C28+O28 -> 18.3 | AL28: =+AA28+AG28 -> 78.65 | AM28: =+AB28+AH28 -> 0 | AN28: =+AD28+AJ28 -> 18.3 | AO28: =+AE28+AK28 -> 0
A29: MARZO DE 2004 | N29: 16.08 | O29: 68 | R29: 0 | T29: 16.08 | U29: 293.646 | W29: 11 | X29: 18.294 | Z29: =IF(AA29=0,"N.A.",((K29*L29)+(W29*X29))/AA29) -> 11 | AA29: =+L29+X29 -> 18.294 | AC29: =IF(AD29=0,"N.A.",((E29*F29)+(Q29*R29))/AD29) -> N.A. | AD29: =+F29+R29 -> 0 | AF29: =IF(AG29=0,"N.A.",((H29*I29)+(T29*U29))/AG29) -> 16.08 | AG29: =+I29+U29 -> 293.646 | AI29: =IF(AJ29=0,"N.A.",((B29*C29)+(N29*O29))/AJ29) -> 16.08 | AJ29: =+C29+O29 -> 68 | AL29: =+AA29+AG29 -> 311.94 | AM29: =+AB29+AH29 -> 0 | AN29: =+AD29+AJ29 -> 68 | AO29: =+AE29+AK29 -> 0
A30: ABRIL DE 2004 | O30: 0 | Q30: 13.91 | R30: 14.287 | T30: 16.08 | U30: 82.3 | X30: 0 | Z30: =IF(AA30=0,"N.A.",((K30*L30)+(W30*X30))/AA30) -> N.A. | AA30: =+L30+X30 -> 0 | AC30: =IF(AD30=0,"N.A.",((E30*F30)+(Q30*R30))/AD30) -> 13.91 | AD30: =+F30+R30 -> 14.287 | AF30: =IF(AG30=0,"N.A.",((H30*I30)+(T30*U30))/AG30) -> 16.08 | AG30: =+I30+U30 -> 82.3 | AI30: =IF(AJ30=0,"N.A.",((B30*C30)+(N30*O30))/AJ30) -> N.A. | AJ30: =+C30+O30 -> 0 | AL30: =+AA30+AG30 -> 82.3 | AM30: =+AB30+AH30 -> 0 | AN30: =+AD30+AJ30 -> 14.287 | AO30: =+AE30+AK30 -> 0
A31: MAYO DE 2004 | N31: 16.08 | O31: 110 | R31: 0 | T31: 16.08 | U31: 139.3 | X31: 0 | Z31: =IF(AA31=0,"N.A.",((K31*L31)+(W31*X31))/AA31) -> N.A. | AA31: =+L31+X31 -> 0 | AC31: =IF(AD31=0,"N.A.",((E31*F31)+(Q31*R31))/AD31) -> N.A. | AD31: =+F31+R31 -> 0 | AF31: =IF(AG31=0,"N.A.",((H31*I31)+(T31*U31))/AG31) -> 16.08 | AG31: =+I31+U31 -> 139.3 | AI31: =IF(AJ31=0,"N.A.",((B31*C31)+(N31*O31))/AJ31) -> 16.08 | AJ31: =+C31+O31 -> 110 | AL31: =+AA31+AG31 -> 139.3 | AM31: =+AB31+AH31 -> 0 | AN31: =+AD31+AJ31 -> 110 | AO31: =+AE31+AK31 -> 0
A32: JUNIO DE 2004 | N32: 16.08 | O32: 36.4 | Q32: 13.91 | R32: 25 | T32: 16.08 | U32: 95 | X32: 0 | Z32: =IF(AA32=0,"N.A.",((K32*L32)+(W32*X32))/AA32) -> N.A. | AA32: =+L32+X32 -> 0 | AC32: =IF(AD32=0,"N.A.",((E32*F32)+(Q32*R32))/AD32) -> 13.91 | AD32: =+F32+R32 -> 25 | AF32: =IF(AG32=0,"N.A.",((H32*I32)+(T32*U32))/AG32) -> 16.08 | AG32: =+I32+U32 -> 95 | AI32: =IF(AJ32=0,"N.A.",((B32*C32)+(N32*O32))/AJ32) -> 16.08 | AJ32: =+C32+O32 -> 36.4 | AL32: =+AA32+AG32 -> 95 | AM32: =+AB32+AH32 -> 0 | AN32: =+AD32+AJ32 -> 61.4 | AO32: =+AE32+AK32 -> 0
A33: JULIO DE 2004 | O33: 0 | R33: 0 | T33: 16.08 | U33: 160.876 | X33: 0 | Z33: =IF(AA33=0,"N.A.",((K33*L33)+(W33*X33))/AA33) -> N.A. | AA33: =+L33+X33 -> 0 | AC33: =IF(AD33=0,"N.A.",((E33*F33)+(Q33*R33))/AD33) -> N.A. | AD33: =+F33+R33 -> 0 | AF33: =IF(AG33=0,"N.A.",((H33*I33)+(T33*U33))/AG33) -> 16.08 | AG33: =+I33+U33 -> 160.876 | AI33: =IF(AJ33=0,"N.A.",((B33*C33)+(N33*O33))/AJ33) -> N.A. | AJ33: =+C33+O33 -> 0 | AL33: =+AA33+AG33 -> 160.876 | AM33: =+AB33+AH33 -> 0 | AN33: =+AD33+AJ33 -> 0 | AO33: =+AE33+AK33 -> 0
A34: AGOSTO DE 2004 | N34: 16.08 | O34: 38.5 | R34: 0 | T34: 16.08 | U34: 161.903 | X34: 0 | Z34: =IF(AA34=0,"N.A.",((K34*L34)+(W34*X34))/AA34) -> N.A. | AA34: =+L34+X34 -> 0 | AC34: =IF(AD34=0,"N.A.",((E34*F34)+(Q34*R34))/AD34) -> N.A. | AD34: =+F34+R34 -> 0 | AF34: =IF(AG34=0,"N.A.",((H34*I34)+(T34*U34))/AG34) -> 16.08 | AG34: =+I34+U34 -> 161.903 | AI34: =IF(AJ34=0,"N.A.",((B34*C34)+(N34*O34))/AJ34) -> 16.08 | AJ34: =+C34+O34 -> 38.5 | AL34: =+AA34+AG34 -> 161.903 | AM34: =+AB34+AH34 -> 0 | AN34: =+AD34+AJ34 -> 38.5 | AO34: =+AE34+AK34 -> 0
A35: SEPTIEMBRE DE 2004 | N35: 16.08 | O35: 75.9 | R35: 0 | T35: 16.08 | U35: 90.567 | X35: 0 | Z35: =IF(AA35=0,"N.A.",((K35*L35)+(W35*X35))/AA35) -> N.A. | AA35: =+L35+X35 -> 0 | AC35: =IF(AD35=0,"N.A.",((E35*F35)+(Q35*R35))/AD35) -> N.A. | AD35: =+F35+R35 -> 0 | AF35: =IF(AG35=0,"N.A.",((H35*I35)+(T35*U35))/AG35) -> 16.08 | AG35: =+I35+U35 -> 90.567 | AI35: =IF(AJ35=0,"N.A.",((B35*C35)+(N35*O35))/AJ35) -> 16.08 | AJ35: =+C35+O35 -> 75.9 | AL35: =+AA35+AG35 -> 90.567 | AM35: =+AB35+AH35 -> 0 | AN35: =+AD35+AJ35 -> 75.9 | AO35: =+AE35+AK35 -> 0
A36: OCTUBRE DE 2004 | N36: 16.08 | O36: 76.2 | R36: 0 | T36: 16.08 | U36: 76.51 | X36: 0 | Z36: =IF(AA36=0,"N.A.",((K36*L36)+(W36*X36))/AA36) -> N.A. | AA36: =+L36+X36 -> 0 | AC36: =IF(AD36=0,"N.A.",((E36*F36)+(Q36*R36))/AD36) -> N.A. | AD36: =+F36+R36 -> 0 | AF36: =IF(AG36=0,"N.A.",((H36*I36)+(T36*U36))/AG36) -> 16.08 | AG36: =+I36+U36 -> 76.51 | AI36: =IF(AJ36=0,"N.A.",((B36*C36)+(N36*O36))/AJ36) -> 16.08 | AJ36: =+C36+O36 -> 76.2 | AL36: =+AA36+AG36 -> 76.51 | AM36: =+AB36+AH36 -> 0 | AN36: =+AD36+AJ36 -> 76.2 | AO36: =+AE36+AK36 -> 0
A37: NOVIEMBRE DE 2004 | O37: 0 | R37: 0 | T37: 16.08 | U37: 84.83 | X37: 0 | Z37: =IF(AA37=0,"N.A.",((K37*L37)+(W37*X37))/AA37) -> N.A. | AA37: =+L37+X37 -> 0 | AC37: =IF(AD37=0,"N.A.",((E37*F37)+(Q37*R37))/AD37) -> N.A. | AD37: =+F37+R37 -> 0 | AF37: =IF(AG37=0,"N.A.",((H37*I37)+(T37*U37))/AG37) -> 16.08 | AG37: =+I37+U37 -> 84.83 | AI37: =IF(AJ37=0,"N.A.",((B37*C37)+(N37*O37))/AJ37) -> N.A. | AJ37: =+C37+O37 -> 0 | AL37: =+AA37+AG37 -> 84.83 | AM37: =+AB37+AH37 -> 0 | AN37: =+AD37+AJ37 -> 0 | AO37: =+AE37+AK37 -> 0
A38: DICIEMBRE DE 2004 | N38: 16.08 | O38: 33.6 | Q38: 13.91 | R38: 442.882 | T38: 16.08 | U38: 236.45 | X38: 0 | Z38: =IF(AA38=0,"N.A.",((K38*L38)+(W38*X38))/AA38) -> N.A. | AA38: =+L38+X38 -> 0 | AC38: =IF(AD38=0,"N.A.",((E38*F38)+(Q38*R38))/AD38) -> 13.91 | AD38: =+F38+R38 -> 442.882 | AF38: =IF(AG38=0,"N.A.",((H38*I38)+(T38*U38))/AG38) -> 16.08 | AG38: =+I38+U38 -> 236.45 | AI38: =IF(AJ38=0,"N.A.",((B38*C38)+(N38*O38))/AJ38) -> 16.08 | AJ38: =+C38+O38 -> 33.6 | AL38: =+AA38+AG38 -> 236.45 | AM38: =+AB38+AH38 -> 0 | AN38: =+AD38+AJ38 -> 476.482 | AO38: =+AE38+AK38 -> 0
A39: ENERO DE 2005 | O39: 0 | R39: 0 | T39: 16.08 | U39: 50.4 | X39: 0 | Z39: =IF(AA39=0,"N.A.",((K39*L39)+(W39*X39))/AA39) -> N.A. | AA39: =+L39+X39 -> 0 | AC39: =IF(AD39=0,"N.A.",((E39*F39)+(Q39*R39))/AD39) -> N.A. | AD39: =+F39+R39 -> 0 | AF39: =IF(AG39=0,"N.A.",((H39*I39)+(T39*U39))/AG39) -> 16.08 | AG39: =+I39+U39 -> 50.4 | AI39: =IF(AJ39=0,"N.A.",((B39*C39)+(N39*O39))/AJ39) -> N.A. | AJ39: =+C39+O39 -> 0 | AL39: =+AA39+AG39 -> 50.4 | AM39: =+AB39+AH39 -> 0 | AN39: =+AD39+AJ39 -> 0 | AO39: =+AE39+AK39 -> 0
A40: FEBRERO DE 2005 | N40: 16.08 | O40: 105 | Q40: 13.91 | R40: 37.581 | T40: 16.08 | U40: 50 | X40: 0 | Z40: =IF(AA40=0,"N.A.",((K40*L40)+(W40*X40))/AA40) -> N.A. | AA40: =+L40+X40 -> 0 | AC40: =IF(AD40=0,"N.A.",((E40*F40)+(Q40*R40))/AD40) -> 13.91 | AD40: =+F40+R40 -> 37.581 | AF40: =IF(AG40=0,"N.A.",((H40*I40)+(T40*U40))/AG40) -> 16.08 | AG40: =+I40+U40 -> 50 | AI40: =IF(AJ40=0,"N.A.",((B40*C40)+(N40*O40))/AJ40) -> 16.08 | AJ40: =+C40+O40 -> 105 | AL40: =+AA40+AG40 -> 50 | AM40: =+AB40+AH40 -> 0 | AN40: =+AD40+AJ40 -> 142.581 | AO40: =+AE40+AK40 -> 0
...

Sheet BANCAFE
A1: TASAS Y DESEMBOLSOS MENSUALES DE CARTERA DE VIVIENDA
A2: BANCAFE | E2: 1000
W3: Cifras en millones de pesos y tasas efectivas anuales
B4: Construcción de Vivienda | D4: Construcción de Vivienda | F4: Construcción de Vivienda | H4: Construcción de Vivienda | J4: Adquisición de Vivienda | L4: Adquisición de Vivienda | N4: Adquisición de Vivienda | P4: Adquisición de Vivienda | R4: CREDITOS DE VIVIENDA en U.V.R. (Puntos) | V4: CREDITOS DE VIVIENDA en Pesos (T.E.A.) | Z4: CONSOLIDADO
A5: PERIODO | B5: diferente de VIS en Pesos | D5: diferente de VIS en UVR | F5: VIS en Pesos | H5: VIS en UVR | J5: diferente de VIS en Pesos | L5: diferente de VIS en UVR | N5: VIS en Pesos | P5: VIS en UVR | R5: VIS | T5: NO VIS | V5: VIS | X5: NO VIS | Z5: VIS | AA5: NO VIS
B6: TASA | C6: MONTO | D6: TASA | E6: MONTO | F6: TASA | G6: MONTO | H6: TASA | I6: MONTO | J6: TASA | K6: MONTO | L6: TASA | M6: MONTO | N6: TASA | O6: MONTO | P6: TASA | Q6: MONTO | R6: TASA | S6: MONTO | T6: TASA | U6: MONTO | V6: TASA | W6: MONTO | X6: TASA | Y6: MONTO | Z6: MONTO | AA6: MONTO
A7: MAYO DE 2002 | J7: 13 | K7: 92.692 | L7: 10.80084 | M7: 198.058 | P7: 11 | Q7: 99.778 | R7: =+((H7*I7)+(P7*Q7))/S7 -> 11 | S7: =+I7+Q7 -> 99.778 | T7: =+((D7*E7)+(L7*M7))/U7 -> 10.80084 | U7: =+E7+M7 -> 198.058 | V7: =IF(W7=0,"N.A.",((F7*G7)+(N7*O7))/W7) -> N.A. | W7: =+G7+O7 -> 0 | X7: =IF(Y7=0,"N.A.",((B7*C7)+(J7*K7))/Y7) -> 13 | Y7: =+C7+K7 -> 92.692 | Z7: =+S7+W7 -> 99.778 | AA7: =+U7+Y7 -> 290.75
A8: JUNIO DE 2002 | L8: 13.9 | M8: 67 | P8: 11 | Q8: 11.27 | R8: =+((H8*I8)+(P8*Q8))/S8 -> 11 | S8: =+I8+Q8 -> 11.27 | T8: =+((D8*E8)+(L8*M8))/U8 -> 13.9 | U8: =+E8+M8 -> 67 | V8: =IF(W8=0,"N.A.",((F8*G8)+(N8*O8))/W8) -> N.A. | W8: =+G8+O8 -> 0 | X8: =IF(Y8=0,"N.A.",((B8*C8)+(J8*K8))/Y8) -> N.A. | Y8: =+C8+K8 -> 0 | Z8: =+S8+W8 -> 11.27 | AA8: =+U8+Y8 -> 67
A9: JULIO DE 2002 | L9: 13.9 | M9: 431.339 | P9: 11 | Q9: 56.779 | R9: =+((H9*I9)+(P9*Q9))/S9 -> 11 | S9: =+I9+Q9 -> 56.779 | T9: =+((D9*E9)+(L9*M9))/U9 -> 13.9 | U9: =+E9+M9 -> 431.339 | V9: =IF(W9=0,"N.A.",((F9*G9)+(N9*O9))/W9) -> N.A. | W9: =+G9+O9 -> 0 | X9: =IF(Y9=0,"N.A.",((B9*C9)+(J9*K9))/Y9) -> N.A. | Y9: =+C9+K9 -> 0 | Z9: =+S9+W9 -> 56.779 | AA9: =+U9+Y9 -> 431.339
A10: AGOSTO DE 2002 | L10: 13.9 | M10: 310.7 | P10: 11 | Q10: 42.2 | R10: =+((H10*I10)+(P10*Q10))/S10 -> 11 | S10: =+I10+Q10 -> 42.2 | T10: =+((D10*E10)+(L10*M10))/U10 -> 13.9 | U10: =+E10+M10 -> 310.7 | V10: =IF(W10=0,"N.A.",((F10*G10)+(N10*O10))/W10) -> N.A. | W10: =+G10+O10 -> 0 | X10: =IF(Y10=0,"N.A.",((B10*C10)+(J10*K10))/Y10) -> N.A. | Y10: =+C10+K10 -> 0 | Z10: =+S10+W10 -> 42.2 | AA10: =+U10+Y10 -> 310.7
A11: SEPTIEMBRE DE 2002 | L11: 13.9 | M11: 109.834 | P11: 11 | Q11: 196.21 | R11: =+((H11*I11)+(P11*Q11))/S11 -> 11 | S11: =+I11+Q11 -> 196.21 | T11: =+((D11*E11)+(L11*M11))/U11 -> 13.9 | U11: =+E11+M11 -> 109.834 | V11: =IF(W11=0,"N.A.",((F11*G11)+(N11*O11))/W11) -> N.A. | W11: =+G11+O11 -> 0 | X11: =IF(Y11=0,"N.A.",((B11*C11)+(J11*K11))/Y11) -> N.A. | Y11: =+C11+K11 -> 0 | Z11: =+S11+W11 -> 196.21 | AA11: =+U11+Y11 -> 109.834
A12: OCTUBRE DE 2002 | L12: 13.9 | M12: 324.385 | R12: =+((H12*I12)+(P12*Q12))/S12 -> #DIV/0! | S12: =+I12+Q12 -> 0 | T12: =+((D12*E12)+(L12*M12))/U12 -> 13.9 | U12: =+E12+M12 -> 324.385 | V12: =IF(W12=0,"N.A.",((F12*G12)+(N12*O12))/W12) -> N.A. | W12: =+G12+O12 -> 0 | X12: =IF(Y12=0,"N.A.",((B12*C12)+(J12*K12))/Y12) -> N.A. | Y12: =+C12+K12 -> 0 | Z12: =+S12+W12 -> 0 | AA12: =+U12+Y12 -> 324.385
A13: NOVIEMBRE DE 2002 | L13: 13.9 | M13: 545.925 | R13: =+((H13*I13)+(P13*Q13))/S13 -> #DIV/0! | S13: =+I13+Q13 -> 0 | T13: =+((D13*E13)+(L13*M13))/U13 -> 13.9 | U13: =+E13+M13 -> 545.925 | V13: =IF(W13=0,"N.A.",((F13*G13)+(N13*O13))/W13) -> N.A. | W13: =+G13+O13 -> 0 | X13: =IF(Y13=0,"N.A.",((B13*C13)+(J13*K13))/Y13) -> N.A. | Y13: =+C13+K13 -> 0 | Z13: =+S13+W13 -> 0 | AA13: =+U13+Y13 -> 545.925
A14: DICIEMBRE DE 2002 | L14: 13.9 | M14: 181.2 | R14: =+((H14*I14)+(P14*Q14))/S14 -> #DIV/0! | S14: =+I14+Q14 -> 0 | T14: =+((D14*E14)+(L14*M14))/U14 -> 13.9 | U14: =+E14+M14 -> 181.2 | V14: =IF(W14=0,"N.A.",((F14*G14)+(N14*O14))/W14) -> N.A. | W14: =+G14+O14 -> 0 | X14: =IF(Y14=0,"N.A.",((B14*C14)+(J14*K14))/Y14) -> N.A. | Y14: =+C14+K14 -> 0 | Z14: =+S14+W14 -> 0 | AA14: =+U14+Y14 -> 181.2
A15: ENERO DE 2003 | L15: 13.9 | M15: 154.84 | R15: =+((H15*I15)+(P15*Q15))/S15 -> #DIV/0! | S15: =+I15+Q15 -> 0 | T15: =+((D15*E15)+(L15*M15))/U15 -> 13.9 | U15: =+E15+M15 -> 154.84 | V15: =IF(W15=0,"N.A.",((F15*G15)+(N15*O15))/W15) -> N.A. | W15: =+G15+O15 -> 0 | X15: =IF(Y15=0,"N.A.",((B15*C15)+(J15*K15))/Y15) -> N.A. | Y15: =+C15+K15 -> 0 | Z15: =+S15+W15 -> 0 | AA15: =+U15+Y15 -> 154.84
A16: FEBRERO DE 2003 | L16: 13.9 | M16: 582.898 | P16: 11 | Q16: 11.725 | R16: =+((H16*I16)+(P16*Q16))/S16 -> 11 | S16: =+I16+Q16 -> 11.725 | T16: =+((D16*E16)+(L16*M16))/U16 -> 13.9 | U16: =+E16+M16 -> 582.898 | V16: =IF(W16=0,"N.A.",((F16*G16)+(N16*O16))/W16) -> N.A. | W16: =+G16+O16 -> 0 | X16: =IF(Y16=0,"N.A.",((B16*C16)+(J16*K16))/Y16) -> N.A. | Y16: =+C16+K16 -> 0 | Z16: =+S16+W16 -> 11.725 | AA16: =+U16+Y16 -> 582.898
A17: MARZO DE 2003 | L17: 13.9 | M17: 608.445 | R17: =+((H17*I17)+(P17*Q17))/S17 -> #DIV/0! | S17: =+I17+Q17 -> 0 | T17: =+((D17*E17)+(L17*M17))/U17 -> 13.9 | U17: =+E17+M17 -> 608.445 | V17: =IF(W17=0,"N.A.",((F17*G17)+(N17*O17))/W17) -> N.A. | W17: =+G17+O17 -> 0 | X17: =IF(Y17=0,"N.A.",((B17*C17)+(J17*K17))/Y17) -> N.A. | Y17: =+C17+K17 -> 0 | Z17: =+S17+W17 -> 0 | AA17: =+U17+Y17 -> 608.445
A18: ABRIL DE 2003 | L18: 13.9 | M18: 627.55 | R18: =+((H18*I18)+(P18*Q18))/S18 -> #DIV/0! | S18: =+I18+Q18 -> 0 | T18: =+((D18*E18)+(L18*M18))/U18 -> 13.9 | U18: =+E18+M18 -> 627.55 | V18: =IF(W18=0,"N.A.",((F18*G18)+(N18*O18))/W18) -> N.A. | W18: =+G18+O18 -> 0 | X18: =IF(Y18=0,"N.A.",((B18*C18)+(J18*K18))/Y18) -> N.A. | Y18: =+C18+K18 -> 0 | Z18: =+S18+W18 -> 0 | AA18: =+U18+Y18 -> 627.55
A19: MAYO DE 2003 | L19: 13.9 | M19: 1046.226 | P19: 11 | Q19: 22.699 | R19: =+((H19*I19)+(P19*Q19))/S19 -> 11 | S19: =+I19+Q19 -> 22.699 | T19: =+((D19*E19)+(L19*M19))/U19 -> 13.9 | U19: =+E19+M19 -> 1046.226 | V19: =IF(W19=0,"N.A.",((F19*G19)+(N19*O19))/W19) -> N.A. | W19: =+G19+O19 -> 0 | X19: =IF(Y19=0,"N.A.",((B19*C19)+(J19*K19))/Y19) -> N.A. | Y19: =+C19+K19 -> 0 | Z19: =+S19+W19 -> 22.699 | AA19: =+U19+Y19 -> 1046.226
A20: JUNIO DE 2003 | L20: 13.9 | M20: 806.65 | R20: =+((H20*I20)+(P20*Q20))/S20 -> #DIV/0! | S20: =+I20+Q20 -> 0 | T20: =+((D20*E20)+(L20*M20))/U20 -> 13.9 | U20: =+E20+M20 -> 806.65 | V20: =IF(W20=0,"N.A.",((F20*G20)+(N20*O20))/W20) -> N.A. | W20: =+G20+O20 -> 0 | X20: =IF(Y20=0,"N.A.",((B20*C20)+(J20*K20))/Y20) -> N.A. | Y20: =+C20+K20 -> 0 | Z20: =+S20+W20 -> 0 | AA20: =+U20+Y20 -> 806.65
A21: JULIO DE 2003 | L21: 13.9 | M21: 1099.855 | P21: 11 | Q21: 39 | R21: =+((H21*I21)+(P21*Q21))/S21 -> 11 | S21: =+I21+Q21 -> 39 | T21: =+((D21*E21)+(L21*M21))/U21 -> 13.9 | U21: =+E21+M21 -> 1099.855 | V21: =IF(W21=0,"N.A.",((F21*G21)+(N21*O21))/W21) -> N.A. | W21: =+G21+O21 -> 0 | X21: =IF(Y21=0,"N.A.",((B21*C21)+(J21*K21))/Y21) -> N.A. | Y21: =+C21+K21 -> 0 | Z21: =+S21+W21 -> 39 | AA21: =+U21+Y21 -> 1099.855
A22: AGOSTO DE 2003 | L22: 13.9 | M22: 1215.732 | R22: =+((H22*I22)+(P22*Q22))/S22 -> #DIV/0! | S22: =+I22+Q22 -> 0 | T22: =+((D22*E22)+(L22*M22))/U22 -> 13.9 | U22: =+E22+M22 -> 1215.732 | V22: =IF(W22=0,"N.A.",((F22*G22)+(N22*O22))/W22) -> N.A. | W22: =+G22+O22 -> 0 | X22: =IF(Y22=0,"N.A.",((B22*C22)+(J22*K22))/Y22) -> N.A. | Y22: =+C22+K22 -> 0 | Z22: =+S22+W22 -> 0 | AA22: =+U22+Y22 -> 1215.732
A23: SEPTIEMBRE DE 2003 | L23: 13.9 | M23: 1305.49 | R23: =+((H23*I23)+(P23*Q23))/S23 -> #DIV/0! | S23: =+I23+Q23 -> 0 | T23: =+((D23*E23)+(L23*M23))/U23 -> 13.9 | U23: =+E23+M23 -> 1305.49 | V23: =IF(W23=0,"N.A.",((F23*G23)+(N23*O23))/W23) -> N.A. | W23: =+G23+O23 -> 0 | X23: =IF(Y23=0,"N.A.",((B23*C23)+(J23*K23))/Y23) -> N.A. | Y23: =+C23+K23 -> 0 | Z23: =+S23+W23 -> 0 | AA23: =+U23+Y23 -> 1305.49
A24: OCTUBRE DE 2003 | L24: 13.9 | M24: 1302.233 | R24: =+((H24*I24)+(P24*Q24))/S24 -> #DIV/0! | S24: =+I24+Q24 -> 0 | T24: =+((D24*E24)+(L24*M24))/U24 -> 13.9 | U24: =+E24+M24 -> 1302.233 | V24: =IF(W24=0,"N.A.",((F24*G24)+(N24*O24))/W24) -> N.A. | W24: =+G24+O24 -> 0 | X24: =IF(Y24=0,"N.A.",((B24*C24)+(J24*K24))/Y24) -> N.A. | Y24: =+C24+K24 -> 0 | Z24: =+S24+W24 -> 0 | AA24: =+U24+Y24 -> 1302.233
A25: NOVIEMBRE DE 2003 | D25: 12.53 | E25: 240.102 | L25: 13.9 | M25: 1036.073 | R25: =+((H25*I25)+(P25*Q25))/S25 -> #DIV/0! | S25: =+I25+Q25 -> 0 | T25: =+((D25*E25)+(L25*M25))/U25 -> 13.642246 | U25: =+E25+M25 -> 1276.175 | V25: =IF(W25=0,"N.A.",((F25*G25)+(N25*O25))/W25) -> N.A. | W25: =+G25+O25 -> 0 | X25: =IF(Y25=0,"N.A.",((B25*C25)+(J25*K25))/Y25) -> N.A. | Y25: =+C25+K25 -> 0 | Z25: =+S25+W25 -> 0 | AA25: =+U25+Y25 -> 1276.175
A26: DICIEMBRE DE 2003 | L26: 13.9 | M26: 1237.963 | R26: =+((H26*I26)+(P26*Q26))/S26 -> #DIV/0! | S26: =+I26+Q26 -> 0 | T26: =+((D26*E26)+(L26*M26))/U26 -> 13.9 | U26: =+E26+M26 -> 1237.963 | V26: =IF(W26=0,"N.A.",((F26*G26)+(N26*O26))/W26) -> N.A. | W26: =+G26+O26 -> 0 | X26: =IF(Y26=0,"N.A.",((B26*C26)+(J26*K26))/Y26) -> N.A. | Y26: =+C26+K26 -> 0 | Z26: =+S26+W26 -> 0 | AA26: =+U26+Y26 -> 1237.963
A27: ENERO DE 2004 | L27: 13.89 | M27: 1254.51 | R27: =+((H27*I27)+(P27*Q27))/S27 -> #DIV/0! | S27: =+I27+Q27 -> 0 | T27: =+((D27*E27)+(L27*M27))/U27 -> 13.89 | U27: =+E27+M27 -> 1254.51 | V27: =IF(W27=0,"N.A.",((F27*G27)+(N27*O27))/W27) -> N.A. | W27: =+G27+O27 -> 0 | X27: =IF(Y27=0,"N.A.",((B27*C27)+(J27*K27))/Y27) -> N.A. | Y27: =+C27+K27 -> 0 | Z27: =+S27+W27 -> 0 | AA27: =+U27+Y27 -> 1254.51
A28: FEBRERO DE 2004 | L28: 13.89 | M28: 1103.546 | R28: =+((H28*I28)+(P28*Q28))/S28 -> #DIV/0! | S28: =+I28+Q28 -> 0 | T28: =+((D28*E28)+(L28*M28))/U28 -> 13.89 | U28: =+E28+M28 -> 1103.546 | V28: =IF(W28=0,"N.A.",((F28*G28)+(N28*O28))/W28) -> N.A. | W28: =+G28+O28 -> 0 | X28: =IF(Y28=0,"N.A.",((B28*C28)+(J28*K28))/Y28) -> N.A. | Y28: =+C28+K28 -> 0 | Z28: =+S28+W28 -> 0 | AA28: =+U28+Y28 -> 1103.546
A29: MARZO DE 2004 | D29: 11.79 | E29: 300 | L29: 13.89 | M29: 1705.483 | R29: =+((H29*I29)+(P29*Q29))/S29 -> #DIV/0! | S29: =+I29+Q29 -> 0 | T29: =+((D29*E29)+(L29*M29))/U29 -> 13.575861 | U29: =+E29+M29 -> 2005.483 | V29: =IF(W29=0,"N.A.",((F29*G29)+(N29*O29))/W29) -> N.A. | W29: =+G29+O29 -> 0 | X29: =IF(Y29=0,"N.A.",((B29*C29)+(J29*K29))/Y29) -> N.A. | Y29: =+C29+K29 -> 0 | Z29: =+S29+W29 -> 0 | AA29: =+U29+Y29 -> 2005.483
A30: ABRIL DE 2004 | L30: 13.89 | M30: 822.876 | P30: 10.99 | Q30: 15.018 | R30: =+((H30*I30)+(P30*Q30))/S30 -> 10.99 | S30: =+I30+Q30 -> 15.018 | T30: =+((D30*E30)+(L30*M30))/U30 -> 13.89 | U30: =+E30+M30 -> 822.876 | V30: =IF(W30=0,"N.A.",((F30*G30)+(N30*O30))/W30) -> N.A. | W30: =+G30+O30 -> 0 | X30: =IF(Y30=0,"N.A.",((B30*C30)+(J30*K30))/Y30) -> N.A. | Y30: =+C30+K30 -> 0 | Z30: =+S30+W30 -> 15.018 | AA30: =+U30+Y30 -> 822.876
A31: MAYO DE 2004 | D31: 10.49 | E31: 500 | L31: 13.89 | M31: 855.899 | P31: 11 | Q31: 7.254 | R31: =+((H31*I31)+(P31*Q31))/S31 -> 11 | S31: =+I31+Q31 -> 7.254 | T31: =+((D31*E31)+(L31*M31))/U31 -> 12.636219 | U31: =+E31+M31 -> 1355.899 | V31: =IF(W31=0,"N.A.",((F31*G31)+(N31*O31))/W31) -> N.A. | W31: =+G31+O31 -> 0 | X31: =IF(Y31=0,"N.A.",((B31*C31)+(J31*K31))/Y31) -> N.A. | Y31: =+C31+K31 -> 0 | Z31: =+S31+W31 -> 7.254 | AA31: =+U31+Y31 -> 1355.899
A32: JUNIO DE 2004 | L32: 13.89 | M32: 1258.691 | P32: 10.99 | Q32: 15.705 | R32: =+((H32*I32)+(P32*Q32))/S32 -> 10.99 | S32: =+I32+Q32 -> 15.705 | T32: =+((D32*E32)+(L32*M32))/U32 -> 13.89 | U32: =+E32+M32 -> 1258.691 | V32: =IF(W32=0,"N.A.",((F32*G32)+(N32*O32))/W32) -> N.A. | W32: =+G32+O32 -> 0 | X32: =IF(Y32=0,"N.A.",((B32*C32)+(J32*K32))/Y32) -> N.A. | Y32: =+C32+K32 -> 0 | Z32: =+S32+W32 -> 15.705 | AA32: =+U32+Y32 -> 1258.691
A33: JULIO DE 2004 | L33: 13.9 | M33: 445.184 | R33: =+((H33*I33)+(P33*Q33))/S33 -> #DIV/0! | S33: =+I33+Q33 -> 0 | T33: =+((D33*E33)+(L33*M33))/U33 -> 13.9 | U33: =+E33+M33 -> 445.184 | V33: =IF(W33=0,"N.A.",((F33*G33)+(N33*O33))/W33) -> N.A. | W33: =+G33+O33 -> 0 | X33: =IF(Y33=0,"N.A.",((B33*C33)+(J33*K33))/Y33) -> N.A. | Y33: =+C33+K33 -> 0 | Z33: =+S33+W33 -> 0 | AA33: =+U33+Y33 -> 445.184
A34: AGOSTO DE 2004 | L34: 13.14 | M34: 644.486 | R34: =+((H34*I34)+(P34*Q34))/S34 -> #DIV/0! | S34: =+I34+Q34 -> 0 | T34: =+((D34*E34)+(L34*M34))/U34 -> 13.14 | U34: =+E34+M34 -> 644.486 | V34: =IF(W34=0,"N.A.",((F34*G34)+(N34*O34))/W34) -> N.A. | W34: =+G34+O34 -> 0 | X34: =IF(Y34=0,"N.A.",((B34*C34)+(J34*K34))/Y34) -> N.A. | Y34: =+C34+K34 -> 0 | Z34: =+S34+W34 -> 0 | AA34: =+U34+Y34 -> 644.486
A35: SEPTIEMBRE DE 2004 | D35: 13.91 | E35: 35 | H35: 8.5 | I35: 700 | J35: 18.81 | K35: 486 | L35: 13.25 | M35: 875.392 | P35: 10.99 | Q35: 22.5 | R35: =+((H35*I35)+(P35*Q35))/S35 -> 8.5775433 | S35: =+I35+Q35 -> 722.5 | T35: =+((D35*E35)+(L35*M35))/U35 -> 13.275374 | U35: =+E35+M35 -> 910.392 | V35: =IF(W35=0,"N.A.",((F35*G35)+(N35*O35))/W35) -> N.A. | W35: =+G35+O35 -> 0 | X35: =IF(Y35=0,"N.A.",((B35*C35)+(J35*K35))/Y35) -> 18.81 | Y35: =+C35+K35 -> 486 | Z35: =+S35+W35 -> 722.5 | AA35: =+U35+Y35 -> 1396.392
A36: OCTUBRE DE 2004 | D36: 8.5 | E36: 200 | J36: 19.51 | K36: 139.4 | L36: 12.19 | M36: 861.6 | R36: =+((H36*I36)+(P36*Q36))/S36 -> #DIV/0! | S36: =+I36+Q36 -> 0 | T36: =+((D36*E36)+(L36*M36))/U36 -> 11.494823 | U36: =+E36+M36 -> 1061.6 | V36: =IF(W36=0,"N.A.",((F36*G36)+(N36*O36))/W36) -> N.A. | W36: =+G36+O36 -> 0 | X36: =IF(Y36=0,"N.A.",((B36*C36)+(J36*K36))/Y36) -> 19.51 | Y36: =+C36+K36 -> 139.4 | Z36: =+S36+W36 -> 0 | AA36: =+U36+Y36 -> 1201
A37: NOVIEMBRE DE 2004 | D37: 9.25 | E37: 500 | J37: 18.82 | K37: 232 | L37: 12.66 | M37: 673.013 | R37: =+((H37*I37)+(P37*Q37))/S37 -> #DIV/0! | S37: =+I37+Q37 -> 0 | T37: =+((D37*E37)+(L37*M37))/U37 -> 11.206478 | U37: =+E37+M37 -> 1173.013 | V37: =IF(W37=0,"N.A.",((F37*G37)+(N37*O37))/W37) -> N.A. | W37: =+G37+O37 -> 0 | X37: =IF(Y37=0,"N.A.",((B37*C37)+(J37*K37))/Y37) -> 18.82 | Y37: =+C37+K37 -> 232 | Z37: =+S37+W37 -> 0 | AA37: =+U37+Y37 -> 1405.013
A38: DICIEMBRE DE 2004 | E38: 0 | J38: 19.1 | K38: 823.9 | L38: 11.78 | M38: 773.609 | P38: 10.99 | Q38: 208.13 | R38: =+((H38*I38)+(P38*Q38))/S38 -> 10.99 | S38: =+I38+Q38 -> 208.13 | T38: =+((D38*E38)+(L38*M38))/U38 -> 11.78 | U38: =+E38+M38 -> 773.609 | V38: =IF(W38=0,"N.A.",((F38*G38)+(N38*O38))/W38) -> N.A. | W38: =+G38+O38 -> 0 | X38: =IF(Y38=0,"N.A.",((B38*C38)+(J38*K38))/Y38) -> 19.1 | Y38: =+C38+K38 -> 823.9 | Z38: =+S38+W38 -> 208.13 | AA38: =+U38+Y38 -> 1597.509
A39: ENERO DE 2005 | D39: 8.52 | E39: 235 | H39: 10.99 | I39: 21.5 | J39: 19.04 | K39: 478.885 | L39: 12.15 | M39: 1311.703 | P39: 10.99 | Q39: 197.086 | R39: =+((H39*I39)+(P39*Q39))/S39 -> 10.99 | S39: =+I39+Q39 -> 218.586 | T39: =+((D39*E39)+(L39*M39))/U39 -> 11.598472 | U39: =+E39+M39 -> 1546.703 | V39: =IF(W39=0,"N.A.",((F39*G39)+(N39*O39))/W39) -> N.A. | W39: =+G39+O39 -> 0 | X39: =IF(Y39=0,"N.A.",((B39*C39)+(J39*K39))/Y39) -> 19.04 | Y39: =+C39+K39 -> 478.885 | Z39: =+S39+W39 -> 218.586 | AA39: =+U39+Y39 -> 2025.588
A40: FEBRERO DE 2005 | J40: 19 | K40: 1038.717 | L40: 11.77 | M40: 2401.404 | P40: 10.99 | Q40: 663.853 | R40: =+((H40*I40)+(P40*Q40))/S40 -> 10.99 | S40: =+I40+Q40 -> 663.853 | T40: =+((D40*E40)+(L40*M40))/U40 -> 11.77 | U40: =+E40+M40 -> 2401.404 | V40: =IF(W40=0,"N.A.",((F40*G40)+(N40*O40))/W40) -> N.A. | W40: =+G40+O40 -> 0 | X40: =IF(Y40=0,"N.A.",((B40*C40)+(J40*K40))/Y40) -> 19 | Y40: =+C40+K40 -> 1038.717 | Z40: =+S40+W40 -> 663.853 | AA40: =+U40+Y40 -> 3440.121
...

Sheet 6- itaú
A1: TASAS Y DESEMBOLSOS MENSUALES DE CARTERA DE VIVIENDA
A2: BANCO ITAÚ
AF3: Cifras en millones de pesos y tasas efectivas anuales promedio ponderadas
A4: MES | B4: Construcción de Vivienda diferente de VIS en pesos | E4: Construcción de Vivienda diferente de VIS en UVR | H4: Construcción de Vivienda VIS en pesos | K4: Construcción de Vivienda VIS en UVR | N4: Adquisición de Vivienda diferente de VIS en Pesos | Q4: Adquisición de Vivienda diferente de VIS en UVR | T4: Adquisición de Vivienda VIS en Pesos | W4: Adquisición de Vivienda VIS en UVR | Z4: CREDITOS DE VIVIENDA en U.V.R. (Puntos) | AF4: CREDITOS DE VIVIENDA en Pesos (T.E.A.) | AL4: CONSOLIDADO
Z5: VIS | AC5: NO VIS | AF5: VIS | AI5: NO VIS | AL5: VIS | AN5: NO VIS
B6: TASA | C6: MONTO | D6: NÚMERO DE CRÉDITOS DESEMBOLSADOS | E6: TASA | F6: MONTO | G6: NÚMERO DE CRÉDITOS DESEMBOLSADOS | H6: TASA | I6: MONTO | J6: NÚMERO DE CRÉDITOS DESEMBOLSADOS | K6: TASA | L6: MONTO | M6: NÚMERO DE CRÉDITOS DESEMBOLSADOS | N6: TASA | O6: MONTO | P6: NÚMERO DE CRÉDITOS DESEMBOLSADOS | Q6: TASA | R6: MONTO | S6: NÚMERO DE CRÉDITOS DESEMBOLSADOS | T6: TASA | U6: MONTO | V6: NÚMERO DE CRÉDITOS DESEMBOLSADOS | W6: TASA | X6: MONTO | Y6: NÚMERO DE CRÉDITOS DESEMBOLSADOS | Z6: TASA | AA6: MONTO | AB6: NÚMERO DE CRÉDITOS DESEMBOLSADOS | AC6: TASA | AD6: MONTO | AE6: NÚMERO DE CRÉDITOS DESEMBOLSADOS | AF6: TASA | AG6: MONTO | AH6: NÚMERO DE CRÉDITOS DESEMBOLSADOS | AI6: TASA | AJ6: MONTO | AK6: NÚMERO DE CRÉDITOS DESEMBOLSADOS | AL6: MONTO | AM6: NÚMERO DE CRÉDITOS DESEMBOLSADOS | AN6: MONTO | AO6: NÚMERO DE CRÉDITOS DESEMBOLSADOS
A7: MARZO DE 2006 | N7: 15.911682 | O7: 8623.697 | Z7: =IF(AA7=0,"N.A.",((K7*L7)+(W7*X7))/AA7) -> N.A. | AA7: =+L7+X7 -> 0 | AC7: =IF(AD7=0,"N.A.",((E7*F7)+(Q7*R7))/AD7) -> N.A. | AD7: =+F7+R7 -> 0 | AF7: =IF(AG7=0,"N.A.",((H7*I7)+(T7*U7))/AG7) -> N.A. | AG7: =+I7+U7 -> 0 | AI7: =IF(AJ7=0,"N.A.",((B7*C7)+(N7*O7))/AJ7) -> 15.911682 | AJ7: =+C7+O7 -> 8623.697 | AL7: =+AA7+AG7 -> 0 | AM7: =+AB7+AH7 -> 0 | AN7: =+AD7+AJ7 -> 8623.697 | AO7: =+AE7+AK7 -> 0
A8: ABRIL DE 2006 | N8: 13.935865 | O8: 6383.838 | Z8: =IF(AA8=0,"N.A.",((K8*L8)+(W8*X8))/AA8) -> N.A. | AA8: =+L8+X8 -> 0 | AC8: =IF(AD8=0,"N.A.",((E8*F8)+(Q8*R8))/AD8) -> N.A. | AD8: =+F8+R8 -> 0 | AF8: =IF(AG8=0,"N.A.",((H8*I8)+(T8*U8))/AG8) -> N.A. | AG8: =+I8+U8 -> 0 | AI8: =IF(AJ8=0,"N.A.",((B8*C8)+(N8*O8))/AJ8) -> 13.935865 | AJ8: =+C8+O8 -> 6383.838 | AL8: =+AA8+AG8 -> 0 | AM8: =+AB8+AH8 -> 0 | AN8: =+AD8+AJ8 -> 6383.838 | AO8: =+AE8+AK8 -> 0
A9: MAYO DE 2006 | N9: 13.34 | O9: 12505.71 | Z9: =IF(AA9=0,"N.A.",((K9*L9)+(W9*X9))/AA9) -> N.A. | AA9: =+L9+X9 -> 0 | AC9: =IF(AD9=0,"N.A.",((E9*F9)+(Q9*R9))/AD9) -> N.A. | AD9: =+F9+R9 -> 0 | AF9: =IF(AG9=0,"N.A.",((H9*I9)+(T9*U9))/AG9) -> N.A. | AG9: =+I9+U9 -> 0 | AI9: =IF(AJ9=0,"N.A.",((B9*C9)+(N9*O9))/AJ9) -> 13.34 | AJ9: =+C9+O9 -> 12505.71 | AL9: =+AA9+AG9 -> 0 | AM9: =+AB9+AH9 -> 0 | AN9: =+AD9+AJ9 -> 12505.71 | AO9: =+AE9+AK9 -> 0
A10: JUNIO DE 2006 | N10: 12.92 | O10: 8725.321 | Z10: =IF(AA10=0,"N.A.",((K10*L10)+(W10*X10))/AA10) -> N.A. | AA10: =+L10+X10 -> 0 | AC10: =IF(AD10=0,"N.A.",((E10*F10)+(Q10*R10))/AD10) -> N.A. | AD10: =+F10+R10 -> 0 | AF10: =IF(AG10=0,"N.A.",((H10*I10)+(T10*U10))/AG10) -> N.A. | AG10: =+I10+U10 -> 0 | AI10: =IF(AJ10=0,"N.A.",((B10*C10)+(N10*O10))/AJ10) -> 12.92 | AJ10: =+C10+O10 -> 8725.321 | AL10: =+AA10+AG10 -> 0 | AM10: =+AB10+AH10 -> 0 | AN10: =+AD10+AJ10 -> 8725.321 | AO10: =+AE10+AK10 -> 0
A11: JULIO DE 2006 | N11: 13.09 | O11: 8447.87 | Z11: =IF(AA11=0,"N.A.",((K11*L11)+(W11*X11))/AA11) -> N.A. | AA11: =+L11+X11 -> 0 | AC11: =IF(AD11=0,"N.A.",((E11*F11)+(Q11*R11))/AD11) -> N.A. | AD11: =+F11+R11 -> 0 | AF11: =IF(AG11=0,"N.A.",((H11*I11)+(T11*U11))/AG11) -> N.A. | AG11: =+I11+U11 -> 0 | AI11: =IF(AJ11=0,"N.A.",((B11*C11)+(N11*O11))/AJ11) -> 13.09 | AJ11: =+C11+O11 -> 8447.87 | AL11: =+AA11+AG11 -> 0 | AM11: =+AB11+AH11 -> 0 | AN11: =+AD11+AJ11 -> 8447.87 | AO11: =+AE11+AK11 -> 0
A12: AGOSTO DE 2006 | N12: 12.95 | O12: 13525.544 | Z12: =IF(AA12=0,"N.A.",((K12*L12)+(W12*X12))/AA12) -> N.A. | AA12: =+L12+X12 -> 0 | AC12: =IF(AD12=0,"N.A.",((E12*F12)+(Q12*R12))/AD12) -> N.A. | AD12: =+F12+R12 -> 0 | AF12: =IF(AG12=0,"N.A.",((H12*I12)+(T12*U12))/AG12) -> N.A. | AG12: =+I12+U12 -> 0 | AI12: =IF(AJ12=0,"N.A.",((B12*C12)+(N12*O12))/AJ12) -> 12.95 | AJ12: =+C12+O12 -> 13525.544 | AL12: =+AA12+AG12 -> 0 | AM12: =+AB12+AH12 -> 0 | AN12: =+AD12+AJ12 -> 13525.544 | AO12: =+AE12+AK12 -> 0
A13: SEPTIEMBRE DE 2006 | N13: 13.3 | O13: 15194.662 | Z13: =IF(AA13=0,"N.A.",((K13*L13)+(W13*X13))/AA13) -> N.A. | AA13: =+L13+X13 -> 0 | AC13: =IF(AD13=0,"N.A.",((E13*F13)+(Q13*R13))/AD13) -> N.A. | AD13: =+F13+R13 -> 0 | AF13: =IF(AG13=0,"N.A.",((H13*I13)+(T13*U13))/AG13) -> N.A. | AG13: =+I13+U13 -> 0 | AI13: =IF(AJ13=0,"N.A.",((B13*C13)+(N13*O13))/AJ13) -> 13.3 | AJ13: =+C13+O13 -> 15194.662 | AL13: =+AA13+AG13 -> 0 | AM13: =+AB13+AH13 -> 0 | AN13: =+AD13+AJ13 -> 15194.662 | AO13: =+AE13+AK13 -> 0
A14: OCTUBRE DE 2006 | N14: 13.06 | O14: 9192.463 | Z14: =IF(AA14=0,"N.A.",((K14*L14)+(W14*X14))/AA14) -> N.A. | AA14: =+L14+X14 -> 0 | AC14: =IF(AD14=0,"N.A.",((E14*F14)+(Q14*R14))/AD14) -> N.A. | AD14: =+F14+R14 -> 0 | AF14: =IF(AG14=0,"N.A.",((H14*I14)+(T14*U14))/AG14) -> N.A. | AG14: =+I14+U14 -> 0 | AI14: =IF(AJ14=0,"N.A.",((B14*C14)+(N14*O14))/AJ14) -> 13.06 | AJ14: =+C14+O14 -> 9192.463 | AL14: =+AA14+AG14 -> 0 | AM14: =+AB14+AH14 -> 0 | AN14: =+AD14+AJ14 -> 9192.463 | AO14: =+AE14+AK14 -> 0
